Workbook
Name MATRIZ_CUM: Ej1_Matriz!$B$16:$I$23
Name MATRIZ_P: Ej1_Matriz!$B$5:$I$12

Sheet Portada
A1: MEFC 2026 - Fundamentos matematicos. Procesos estocasticos
A2: Hojas de calculo del trabajo (una pestana por apartado)
A4: Hoja | B4: Contenido
A5: Ej1_Matriz | B5: Matriz de transicion a 1 ano P y matriz de acumuladas por filas (para simular)
A6: Ej1a_PD | B6: Potencias P^1 ... P^25 calculadas con MMULT (formulas matriciales vivas)
A7: Ej1a_Res | B7: 1.a) PD acumulada y PD marginal por rating y ano + graficos
A8: Ej1b_Cohorte | B8: 1.b) Cohorte de 5002 companias: proporcion y numero esperado de defaults por ano
A9: Ej1c_25anos | B9: 1.c) Distribucion a 25 anos (P^25) y comprobacion por simulacion de Montecarlo
A10: Ej2c_Mt | B10: 2.c) Trayectoria simulada de M_t y comprobacion empirica de E(M_1) y V(M_1)
A11: Ej3_Calib | B11: 3.3) Calibracion de sigma(t)=a t^2+b t+c a las 3 calls de mercado (listo para Solver)
A12: Ej3_Asiatica | B12: 3.4) Valoracion por simulacion de la opcion asiatica con 4 fijaciones
A15: Nota sobre los datos
A16: El fichero matriz-ratings.xlsx contiene 9 filas y 8 columnas. Las columnas definen el espacio de estados
A17: (Aaa, Aa, A, Baa, Ba, B, Caa-C, Default), que es el mismo de la cohorte del apartado 1.b. Se han usado por tanto
A18: las 7 filas de rating (la fila etiquetada Caa es la del estado agregado Caa-C: su elemento diagonal cae en esa columna)
A19: mas la fila Default, que es absorbente. La fila sobrante Ca-C del fichero no forma parte de la cadena de 8 estados.

Sheet Ej1_Matriz
A1: Ejercicio 1 - Matriz de transicion a 1 ano
A3: P (probabilidades de transicion a 1 ano)
B4: Aaa | C4: Aa | D4: A | E4: Baa | F4: Ba | G4: B | H4: Caa-C | I4: Default | K4: Suma
A5: Aaa | B5: 0.82391007 | C5: 0.1335319 | D5: 0.042329488 | E5: 0.00022844852 | F5: 1.0296059e-07 | G5: 4.904662e-12 | H5: 3.8923066e-16 | I5: 5.2162541e-22 | K5: =SUM(B5:I5) -> 1
A6: Aa | B6: 0.32614394 | C6: 0.58132529 | D6: 0.076704585 | E6: 0.015798486 | F6: 2.7651626e-05 | G6: 4.8160506e-08 | H6: 8.977053e-12 | I6: 2.3113048e-16 | K6: =SUM(B6:I6) -> 1
A7: A | B7: 0.016702339 | C7: 0.17825993 | D7: 0.54255942 | E7: 0.24177087 | F7: 0.020648738 | G7: 5.8457996e-05 | H7: 2.49645e-07 | I7: 9.9454781e-12 | K7: =SUM(B7:I7) -> 1
A8: Baa | B8: 4.9559035e-05 | C8: 0.0090075253 | D8: 0.39030448 | E8: 0.34068829 | F8: 0.23608376 | G8: 0.023824729 | H8: 4.1438464e-05 | I8: 2.1532906e-07 | K8: =SUM(B8:I8) -> 1
A9: Ba | B9: 1.0325417e-07 | C9: 0.00014213537 | D9: 0.014813254 | E9: 0.09253187 | F9: 0.63354917 | G9: 0.24603514 | H9: 0.012803846 | I9: 0.00012448746 | K9: =SUM(B9:I9) -> 1
A10: B | B10: 1.5024787e-11 | C10: 1.4168042e-07 | D10: 0.00023401435 | E10: 0.018384244 | F10: 0.11761412 | G10: 0.35144206 | H10: 0.50612649 | I10: 0.0061989228 | K10: =SUM(B10:I10) -> 1
A11: Caa-C | B11: 2.3732356e-16 | C11: 1.4570894e-11 | D11: 1.5543813e-07 | E11: 5.9218757e-05 | F11: 0.0059673241 | G11: 0.12054539 | H11: 0.51822768 | I11: 0.35520024 | K11: =SUM(B11:I11) -> 1
A12: Default | B12: 0 | C12: 0 | D12: 0 | E12: 0 | F12: 0 | G12: 0 | H12: 0 | I12: 1 | K12: =SUM(B12:I12) -> 1
A14: Acumuladas por filas de P (se usan para simular la cadena de Markov)
B15: Aaa | C15: Aa | D15: A | E15: Baa | F15: Ba | G15: B | H15: Caa-C | I15: Default
A16: Aaa | B16: =SUM($B5:B5) -> 0.82391007 | C16: =SUM($B5:C5) -> 0.95744196 | D16: =SUM($B5:D5) -> 0.99977145 | E16: =SUM($B5:E5) -> 0.9999999 | F16: =SUM($B5:F5) -> 1 | G16: =SUM($B5:G5) -> 1 | H16: =SUM($B5:H5) -> 1 | I16: =SUM($B5:I5) -> 1
A17: Aa | B17: =SUM($B6:B6) -> 0.32614394 | C17: =SUM($B6:C6) -> 0.90746923 | D17: =SUM($B6:D6) -> 0.98417381 | E17: =SUM($B6:E6) -> 0.9999723 | F17: =SUM($B6:F6) -> 0.99999995 | G17: =SUM($B6:G6) -> 1 | H17: =SUM($B6:H6) -> 1 | I17: =SUM($B6:I6) -> 1
A18: A | B18: =SUM($B7:B7) -> 0.016702339 | C18: =SUM($B7:C7) -> 0.19496227 | D18: =SUM($B7:D7) -> 0.73752168 | E18: =SUM($B7:E7) -> 0.97929255 | F18: =SUM($B7:F7) -> 0.99994129 | G18: =SUM($B7:G7) -> 0.99999975 | H18: =SUM($B7:H7) -> 1 | I18: =SUM($B7:I7) -> 1
A19: Baa | B19: =SUM($B8:B8) -> 4.9559035e-05 | C19: =SUM($B8:C8) -> 0.0090570844 | D19: =SUM($B8:D8) -> 0.39936156 | E19: =SUM($B8:E8) -> 0.74004986 | F19: =SUM($B8:F8) -> 0.97613362 | G19: =SUM($B8:G8) -> 0.99995835 | H19: =SUM($B8:H8) -> 0.99999978 | I19: =SUM($B8:I8) -> 1
A20: Ba | B20: =SUM($B9:B9) -> 1.0325417e-07 | C20: =SUM($B9:C9) -> 0.00014223862 | D20: =SUM($B9:D9) -> 0.014955492 | E20: =SUM($B9:E9) -> 0.10748736 | F20: =SUM($B9:F9) -> 0.74103653 | G20: =SUM($B9:G9) -> 0.98707167 | H20: =SUM($B9:H9) -> 0.99987551 | I20: =SUM($B9:I9) -> 1
A21: B | B21: =SUM($B10:B10) -> 1.5024787e-11 | C21: =SUM($B10:C10) -> 1.4169545e-07 | D21: =SUM($B10:D10) -> 0.00023415605 | E21: =SUM($B10:E10) -> 0.0186184 | F21: =SUM($B10:F10) -> 0.13623252 | G21: =SUM($B10:G10) -> 0.48767458 | H21: =SUM($B10:H10) -> 0.99380108 | I21: =SUM($B10:I10) -> 1
A22: Caa-C | B22: =SUM($B11:B11) -> 2.3732356e-16 | C22: =SUM($B11:C11) -> 1.4571131e-11 | D22: =SUM($B11:D11) -> 1.554527e-07 | E22: =SUM($B11:E11) -> 5.937421e-05 | F22: =SUM($B11:F11) -> 0.0060266983 | G22: =SUM($B11:G11) -> 0.12657208 | H22: =SUM($B11:H11) -> 0.64479976 | I22: =SUM($B11:I11) -> 1
A23: Default | B23: =SUM($B12:B12) -> 0 | C23: =SUM($B12:C12) -> 0 | D23: =SUM($B12:D12) -> 0 | E23: =SUM($B12:E12) -> 0 | F23: =SUM($B12:F12) -> 0 | G23: =SUM($B12:G12) -> 0 | H23: =SUM($B12:H12) -> 0 | I23: =SUM($B12:I12) -> 1

Sheet Ej1a_PD
A1: Ejercicio 1.a - Potencias de la matriz de transicion: P^n = P^(n-1) x P (MMULT)
A2: Cada bloque es una formula matricial viva. La columna Default (col. I) da la PD acumulada a n anos.
A3: P^1 | B3: Aaa | C3: Aa | D3: A | E3: Baa | F3: Ba | G3: B | H3: Caa-C | I3: Default
A4: Aaa | B4: {=MATRIZ_P} -> 0.82391007 | C4: 0.1335319 | D4: 0.042329488 | E4: 0.00022844852 | F4: 1.0296059e-07 | G4: 4.904662e-12 | H4: 3.8923066e-16 | I4: 5.2162541e-22
A5: Aa | B5: 0.32614394 | C5: 0.58132529 | D5: 0.076704585 | E5: 0.015798486 | F5: 2.7651626e-05 | G5: 4.8160506e-08 | H5: 8.977053e-12 | I5: 2.3113048e-16
A6: A | B6: 0.016702339 | C6: 0.17825993 | D6: 0.54255942 | E6: 0.24177087 | F6: 0.020648738 | G6: 5.8457996e-05 | H6: 2.49645e-07 | I6: 9.9454781e-12
A7: Baa | B7: 4.9559035e-05 | C7: 0.0090075253 | D7: 0.39030448 | E7: 0.34068829 | F7: 0.23608376 | G7: 0.023824729 | H7: 4.1438464e-05 | I7: 2.1532906e-07
A8: Ba | B8: 1.0325417e-07 | C8: 0.00014213537 | D8: 0.014813254 | E8: 0.09253187 | F8: 0.63354917 | G8: 0.24603514 | H8: 0.012803846 | I8: 0.00012448746
A9: B | B9: 1.5024787e-11 | C9: 1.4168042e-07 | D9: 0.00023401435 | E9: 0.018384244 | F9: 0.11761412 | G9: 0.35144206 | H9: 0.50612649 | I9: 0.0061989228
A10: Caa-C | B10: 2.3732356e-16 | C10: 1.4570894e-11 | D10: 1.5543813e-07 | E10: 5.9218757e-05 | F10: 0.0059673241 | G10: 0.12054539 | H10: 0.51822768 | I10: 0.35520024
A11: Default | B11: 0 | C11: 0 | D11: 0 | E11: 0 | F11: 0 | G11: 0 | H11: 0 | I11: 1
A13: P^2 | B13: Aaa | C13: Aa | D13: A | E13: Baa | F13: Ba | G13: B | H13: Caa-C | I13: Default
A14: Aaa | B14: {=MMULT($B$4:$I$11,MATRIZ_P)} -> 0.72308543 | C14: 0.19519145 | D14: 0.068173628 | E14: 0.012609699 | F14: 0.00093182594 | G14: 7.9489896e-06 | H14: 2.1355874e-08 | I14: 6.2460465e-11
A15: Aa | B15: 0.45959092 | C15: 0.39530538 | D15: 0.10617925 | E15: 0.033188419 | F15: 0.0053472513 | G15: 0.00038772683 | H15: 1.0522462e-06 | I15: 7.1466488e-09
A16: A | B16: 0.080973616 | C16: 0.20475459 | D16: 0.40342122 | E16: 0.21827536 | F16: 0.081375143 | G16: 0.010892741 | H16: 0.00030425384 | I16: 3.0736352e-06
A17: Baa | B17: 0.0095144883 | C17: 0.077920886 | D17: 0.3489313 | E17: 0.23285836 | F17: 0.24086356 | G17: 0.074602531 | H17: 0.015116796 | I17: 0.00019208477
A18: Ba | B18: 0.00029850886 | C18: 0.003646818 | D18: 0.053606083 | E18: 0.098255601 | F18: 0.45254931 | G18: 0.24609131 | H18: 0.13927591 | I18: 0.0062764583
A19: B | B19: 4.8780624e-06 | C19: 0.00022416121 | D19: 0.0091269992 | E19: 0.0236939 | F19: 0.12321415 | G19: 0.21389796 | H19: 0.44166957 | I19: 0.18816838
A20: Caa-C | B20: 6.1537196e-09 | C20: 1.4263856e-06 | D20: 0.00013988307 | E20: 0.0028192049 | F20: 0.021064849 | G20: 0.10630426 | H20: 0.32964755 | I20: 0.54002283
A21: Default | B21: 0 | C21: 0 | D21: 0 | E21: 0 | F21: 0 | G21: 0 | H21: 0 | I21: 1
A23: P^3 | B23: Aaa | C23: Aa | D23: A | E23: Baa | F23: Ba | G23: B | H23: Caa-C | I23: Default
A24: Aaa | B24: {=MMULT($B$14:$I$21,MATRIZ_P)} -> 0.66055715 | C24: 0.22229104 | D24: 0.087503586 | E24: 0.024113661 | F24: 0.004981409 | G24: 0.00053647547 | H24: 1.6504765e-05 | I24: 1.756398e-07
A25: Aa | B25: 0.50936313 | C25: 0.31039827 | D25: 0.12041742 | E25: 0.043830093 | F25: 0.013472047 | G25: 0.0022489332 | H25: 0.00026665129 | I25: 3.4572067e-06
A26: A | B26: 0.14024335 | C26: 0.20373311 | D26: 0.324415 | E26: 0.18288274 | F26: 0.11270519 | G26: 0.029109933 | H26: 0.006721838 | I26: 0.00018884512
A27: Baa | B27: 0.039092041 | C27: 0.11090006 | D27: 0.29016669 | E27: 0.18858671 | F27: 0.22364465 | G27: 0.092869815 | H27: 0.048685976 | I27: 0.0060540643
A28: Ba | B28: 0.0023355952 | C28: 0.012665062 | D28: 0.074487788 | E28: 0.092900289 | F28: 0.34079071 | G28: 0.21696298 | H28: 0.20252842 | I28: 0.057329154
A29: B | B29: 0.00023075711 | C29: 0.001988907 | D29: 0.016092502 | E29: 0.025642163 | F29: 0.11163744 | G29: 0.15929401 | H29: 0.33872342 | I29: 0.3463908
A30: Caa-C | B30: 2.9485453e-06 | C30: 5.4168747e-05 | D30: 0.0015133198 | E30: 0.0049173268 | F30: 0.02848407 | G30: 0.082347146 | H30: 0.22490571 | I30: 0.65777531
A31: Default | B31: 0 | C31: 0 | D31: 0 | E31: 0 | F31: 0 | G31: 0 | H31: 0 | I31: 1
A33: P^4 | B33: Aaa | C33: Aa | D33: A | E33: Baa | F33: Ba | G33: B | H33: Caa-C | I33: Default
A34: Aaa | B34: {=MMULT($B$24:$I$31,MATRIZ_P)} -> 0.61820127 | C34: 0.23324514 | D34: 0.10197327 | E34: 0.033504628 | F34: 0.01072506 | G34: 0.0019957587 | H34: 0.00034487995 | I34: 9.9890223e-06
A35: Aa | B35: 0.52291735 | C35: 0.27032091 | D35: 0.12801083 | E35: 0.050353965 | F35: 0.021643978 | G35: 0.0051884048 | H35: 0.0014507711 | I35: 0.00011379931
A36: A | B36: 0.18742179 | C36: 0.19665571 | D36: 0.2706344 | E36: 0.1549552 | F36: 0.12474818 | G36: 0.043146284 | H36: 0.01966747 | I36: 0.0027709636
A37: Baa | B37: 0.073233541 | C37: 0.12314464 | D37: 0.24453484 | E37: 0.1585686 | F37: 0.20342011 | G37: 0.098041666 | H37: 0.075105693 | I37: 0.023950909
A38: Ba | B38: 0.0073037132 | C38: 0.021837856 | D38: 0.082842806 | E38: 0.085394335 | F38: 0.26610481 | G38: 0.18672795 | H38: 0.21913385 | I38: 0.13065468
A39: B | B39: 0.0011088578 | C39: 0.0043025262 | D39: 0.020592759 | E39: 0.025936737 | F39: 0.09787035 | G39: 0.12489275 | H39: 0.25758923 | I39: 0.46770679
A40: Caa-C | B40: 4.5618765e-05 | C40: 0.00035000087 | D40: 0.0031858475 | E40: 0.0062049017 | F40: 0.030265482 | G40: 0.063176921 | H40: 0.15859535 | I40: 0.73817588
A41: Default | B41: 0 | C41: 0 | D41: 0 | E41: 0 | F41: 0 | G41: 0 | H41: 0 | I41: 1
A43: P^5 | B43: Aaa | C43: Aa | D43: A | E43: Baa | F43: Ba | G43: B | H43: Caa-C | I43: Default
A44: Aaa | B44: {=MMULT($B$34:$I$41,MATRIZ_P)} -> 0.58711859 | C44: 0.23662196 | D44: 0.11262202 | E44: 0.040924068 | F44: 0.017053672 | G44: 0.00418592 | H44: 0.0013275685 | I44: 0.00014620437
...

Sheet Ej1a_Res
A1: Ejercicio 1.a - Probabilidad de default acumulada y marginal (exactamente en el ano n)
A3: PD ACUMULADA P(default en <= n anos) | J3: PD MARGINAL P(default exactamente en el ano n)
A4: Ano | B4: Aaa | C4: Aa | D4: A | E4: Baa | F4: Ba | G4: B | H4: Caa-C | J4: Ano | K4: Aaa | L4: Aa | M4: A | N4: Baa | O4: Ba | P4: B | Q4: Caa-C
A5: 1 | B5: =Ej1a_PD!$I$4 -> 5.2162541e-22 | C5: =Ej1a_PD!$I$5 -> 2.3113048e-16 | D5: =Ej1a_PD!$I$6 -> 9.9454781e-12 | E5: =Ej1a_PD!$I$7 -> 2.1532906e-07 | F5: =Ej1a_PD!$I$8 -> 0.00012448746 | G5: =Ej1a_PD!$I$9 -> 0.0061989228 | H5: =Ej1a_PD!$I$10 -> 0.35520024 | J5: 1 | K5: =B5 -> 5.2162541e-22 | L5: =C5 -> 2.3113048e-16 | M5: =D5 -> 9.9454781e-12 | N5: =E5 -> 2.1532906e-07 | O5: =F5 -> 0.00012448746 | P5: =G5 -> 0.0061989228 | Q5: =H5 -> 0.35520024
A6: 2 | B6: =Ej1a_PD!$I$14 -> 6.2460465e-11 | C6: =Ej1a_PD!$I$15 -> 7.1466488e-09 | D6: =Ej1a_PD!$I$16 -> 3.0736352e-06 | E6: =Ej1a_PD!$I$17 -> 0.00019208477 | F6: =Ej1a_PD!$I$18 -> 0.0062764583 | G6: =Ej1a_PD!$I$19 -> 0.18816838 | H6: =Ej1a_PD!$I$20 -> 0.54002283 | J6: 2 | K6: =B6-B5 -> 6.2460465e-11 | L6: =C6-C5 -> 7.1466486e-09 | M6: =D6-D5 -> 3.0736252e-06 | N6: =E6-E5 -> 0.00019186944 | O6: =F6-F5 -> 0.0061519708 | P6: =G6-G5 -> 0.18196946 | Q6: =H6-H5 -> 0.18482259
A7: 3 | B7: =Ej1a_PD!$I$24 -> 1.756398e-07 | C7: =Ej1a_PD!$I$25 -> 3.4572067e-06 | D7: =Ej1a_PD!$I$26 -> 0.00018884512 | E7: =Ej1a_PD!$I$27 -> 0.0060540643 | F7: =Ej1a_PD!$I$28 -> 0.057329154 | G7: =Ej1a_PD!$I$29 -> 0.3463908 | H7: =Ej1a_PD!$I$30 -> 0.65777531 | J7: 3 | K7: =B7-B6 -> 1.7557734e-07 | L7: =C7-C6 -> 3.45006e-06 | M7: =D7-D6 -> 0.00018577149 | N7: =E7-E6 -> 0.0058619796 | O7: =F7-F6 -> 0.051052696 | P7: =G7-G6 -> 0.15822242 | Q7: =H7-H6 -> 0.11775248
A8: 4 | B8: =Ej1a_PD!$I$34 -> 9.9890223e-06 | C8: =Ej1a_PD!$I$35 -> 0.00011379931 | D8: =Ej1a_PD!$I$36 -> 0.0027709636 | E8: =Ej1a_PD!$I$37 -> 0.023950909 | F8: =Ej1a_PD!$I$38 -> 0.13065468 | G8: =Ej1a_PD!$I$39 -> 0.46770679 | H8: =Ej1a_PD!$I$40 -> 0.73817588 | J8: 4 | K8: =B8-B7 -> 9.8133825e-06 | L8: =C8-C7 -> 0.00011034211 | M8: =D8-D7 -> 0.0025821184 | N8: =E8-E7 -> 0.017896845 | O8: =F8-F7 -> 0.073325524 | P8: =G8-G7 -> 0.12131599 | Q8: =H8-H7 -> 0.080400573
A9: 5 | B9: =Ej1a_PD!$I$44 -> 0.00014620437 | C9: =Ej1a_PD!$I$45 -> 0.00066398132 | D9: =Ej1a_PD!$I$46 -> 0.010039877 | E9: =Ej1a_PD!$I$47 -> 0.051261579 | F9: =Ej1a_PD!$I$48 -> 0.20968173 | G9: =Ej1a_PD!$I$49 -> 0.55998893 | H9: =Ej1a_PD!$I$50 -> 0.79490438 | J9: 5 | K9: =B9-B8 -> 0.00013621534 | L9: =C9-C8 -> 0.00055018201 | M9: =D9-D8 -> 0.0072689134 | N9: =E9-E8 -> 0.02731067 | O9: =F9-F8 -> 0.079027052 | P9: =G9-G8 -> 0.092282144 | Q9: =H9-H8 -> 0.056728503
A10: 6 | B10: =Ej1a_PD!$I$54 -> 0.000645837 | C10: =Ej1a_PD!$I$55 -> 0.0020194577 | D10: =Ej1a_PD!$I$56 -> 0.022324187 | E10: =Ej1a_PD!$I$57 -> 0.084266008 | F10: =Ej1a_PD!$I$58 -> 0.28581511 | G10: =Ej1a_PD!$I$59 -> 0.63093104 | H10: =Ej1a_PD!$I$60 -> 0.83590005 | J10: 6 | K10: =B10-B9 -> 0.00049963264 | L10: =C10-C9 -> 0.0013554764 | M10: =D10-D9 -> 0.01228431 | N10: =E10-E9 -> 0.033004429 | O10: =F10-F9 -> 0.076133378 | P10: =G10-G9 -> 0.07094211 | Q10: =H10-H9 -> 0.040995665
A11: 7 | B11: =Ej1a_PD!$I$64 -> 0.0017660249 | C11: =Ej1a_PD!$I$65 -> 0.0044361741 | D11: =Ej1a_PD!$I$66 -> 0.038794852 | E11: =Ej1a_PD!$I$67 -> 0.11998282 | F11: =Ej1a_PD!$I$68 -> 0.35526463 | G11: =Ej1a_PD!$I$69 -> 0.68617607 | H11: =Ej1a_PD!$I$70 -> 0.86615315 | J11: 7 | K11: =B11-B10 -> 0.0011201879 | L11: =C11-C10 -> 0.0024167164 | M11: =D11-D10 -> 0.016470665 | N11: =E11-E10 -> 0.035716808 | O11: =F11-F10 -> 0.069449517 | P11: =G11-G10 -> 0.05524503 | Q11: =H11-H10 -> 0.030253101
A12: 8 | B12: =Ej1a_PD!$I$74 -> 0.0037170291 | C12: =Ej1a_PD!$I$75 -> 0.0080359851 | D12: =Ej1a_PD!$I$76 -> 0.058253246 | E12: =Ej1a_PD!$I$77 -> 0.15631487 | F12: =Ej1a_PD!$I$78 -> 0.41679315 | G12: =Ej1a_PD!$I$79 -> 0.72973212 | H12: =Ej1a_PD!$I$80 -> 0.88890722 | J12: 8 | K12: =B12-B11 -> 0.0019510042 | L12: =C12-C11 -> 0.0035998109 | M12: =D12-D11 -> 0.019458394 | N12: =E12-E11 -> 0.036332051 | O12: =F12-F11 -> 0.061528529 | P12: =G12-G11 -> 0.043556049 | Q12: =H12-H11 -> 0.022754074
A13: 9 | B13: =Ej1a_PD!$I$84 -> 0.0066371409 | C13: =Ej1a_PD!$I$85 -> 0.012833197 | D13: =Ej1a_PD!$I$86 -> 0.079541939 | E13: =Ej1a_PD!$I$87 -> 0.19188453 | F13: =Ej1a_PD!$I$88 -> 0.47043279 | G13: =Ej1a_PD!$I$89 -> 0.7644651 | H13: =Ej1a_PD!$I$90 -> 0.90631881 | J13: 9 | K13: =B13-B12 -> 0.0029201118 | L13: =C13-C12 -> 0.0047972122 | M13: =D13-D12 -> 0.021288693 | N13: =E13-E12 -> 0.035569665 | O13: =F13-F12 -> 0.053639633 | P13: =G13-G12 -> 0.034732982 | Q13: =H13-H12 -> 0.017411587
A14: 10 | B14: =Ej1a_PD!$I$94 -> 0.010592902 | C14: =Ej1a_PD!$I$95 -> 0.018770687 | D14: =Ej1a_PD!$I$96 -> 0.10170558 | E14: =Ej1a_PD!$I$97 -> 0.2258468 | F14: =Ej1a_PD!$I$98 -> 0.51679197 | G14: =Ej1a_PD!$I$99 -> 0.79245188 | H14: =Ej1a_PD!$I$100 -> 0.91985107 | J14: 10 | K14: =B14-B13 -> 0.0039557612 | L14: =C14-C13 -> 0.0059374897 | M14: =D14-D13 -> 0.022163639 | N14: =E14-E13 -> 0.033962268 | O14: =F14-F13 -> 0.046359179 | P14: =G14-G13 -> 0.027986779 | Q14: =H14-H13 -> 0.013532262
A15: 11 | B15: =Ej1a_PD!$I$104 -> 0.015590877 | C15: =Ej1a_PD!$I$105 -> 0.025750336 | D15: =Ej1a_PD!$I$106 -> 0.12402514 | E15: =Ej1a_PD!$I$107 -> 0.25773358 | F15: =Ej1a_PD!$I$108 -> 0.55669353 | G15: =Ej1a_PD!$I$109 -> 0.8152187 | H15: =Ej1a_PD!$I$110 -> 0.9305162 | J15: 11 | K15: =B15-B14 -> 0.0049979746 | L15: =C15-C14 -> 0.0069796488 | M15: =D15-D14 -> 0.022319563 | N15: =E15-E14 -> 0.03188678 | O15: =F15-F14 -> 0.039901567 | P15: =G15-G14 -> 0.02276682 | Q15: =H15-H14 -> 0.010665124
A16: 12 | B16: =Ej1a_PD!$I$114 -> 0.021592828 | C16: =Ej1a_PD!$I$115 -> 0.033654721 | D16: =Ej1a_PD!$I$116 -> 0.14599704 | E16: =Ej1a_PD!$I$117 -> 0.28733454 | F16: =Ej1a_PD!$I$118 -> 0.59099329 | G16: =Ej1a_PD!$I$119 -> 0.83390225 | H16: =Ej1a_PD!$I$120 -> 0.93902759 | J16: 12 | K16: =B16-B15 -> 0.0060019515 | L16: =C16-C15 -> 0.0079043856 | M16: =D16-D15 -> 0.021971904 | N16: =E16-E15 -> 0.029600962 | O16: =F16-F15 -> 0.034299758 | P16: =G16-G15 -> 0.018683546 | Q16: =H16-H15 -> 0.0085113951
A17: 13 | B17: =Ej1a_PD!$I$124 -> 0.028530209 | C17: =Ej1a_PD!$I$125 -> 0.042361186 | D17: =Ej1a_PD!$I$126 -> 0.16729338 | E17: =Ej1a_PD!$I$127 -> 0.31460957 | F17: =Ej1a_PD!$I$128 -> 0.62049529 | G17: =Ej1a_PD!$I$129 -> 0.84935975 | H17: =Ej1a_PD!$I$130 -> 0.94589708 | J17: 13 | K17: =B17-B16 -> 0.0069373811 | L17: =C17-C16 -> 0.0087064648 | M17: =D17-D16 -> 0.021296337 | N17: =E17-E16 -> 0.027275029 | O17: =F17-F16 -> 0.029502002 | P17: =G17-G16 -> 0.015457497 | Q17: =H17-H16 -> 0.0068694899
A18: 14 | B18: =Ej1a_PD!$I$134 -> 0.036316275 | C18: =Ej1a_PD!$I$135 -> 0.051750307 | D18: =Ej1a_PD!$I$136 -> 0.18772019 | E18: =Ej1a_PD!$I$137 -> 0.33962618 | F18: =Ej1a_PD!$I$138 -> 0.64591782 | G18: =Ej1a_PD!$I$139 -> 0.86224526 | H18: =Ej1a_PD!$I$140 -> 0.95149804 | J18: 14 | K18: =B18-B17 -> 0.0077860659 | L18: =C18-C17 -> 0.0093891204 | M18: =D18-D17 -> 0.020426804 | N18: =E18-E17 -> 0.025016605 | O18: =F18-F17 -> 0.025422528 | P18: =G18-G17 -> 0.012885513 | Q18: =H18-H17 -> 0.0056009562
A19: 15 | B19: =Ej1a_PD!$I$144 -> 0.044855414 | C19: =Ej1a_PD!$I$145 -> 0.061710575 | D19: =Ej1a_PD!$I$146 -> 0.20718067 | E19: =Ej1a_PD!$I$147 -> 0.36251575 | F19: =Ej1a_PD!$I$148 -> 0.667885 | G19: =Ej1a_PD!$I$149 -> 0.8730633 | H19: =Ej1a_PD!$I$150 -> 0.95610709 | J19: 15 | K19: =B19-B18 -> 0.0085391389 | L19: =C19-C18 -> 0.0099602689 | M19: =D19-D18 -> 0.019460489 | N19: =E19-E18 -> 0.022889568 | O19: =F19-F18 -> 0.02196718 | P19: =G19-G18 -> 0.010818045 | Q19: =H19-H18 -> 0.0046090488
A20: 16 | B20: =Ej1a_PD!$I$154 -> 0.054049894 | C20: =Ej1a_PD!$I$155 -> 0.072140657 | D20: =Ej1a_PD!$I$156 -> 0.22564555 | E20: =Ej1a_PD!$I$157 -> 0.38344363 | F20: =Ej1a_PD!$I$158 -> 0.68693063 | G20: =Ej1a_PD!$I$159 -> 0.88220699 | H20: =Ej1a_PD!$I$160 -> 0.95993213 | J20: 16 | K20: =B20-B19 -> 0.0091944799 | L20: =C20-C19 -> 0.010430082 | M20: =D20-D19 -> 0.018464871 | N20: =E20-E19 -> 0.020927887 | O20: =F20-F19 -> 0.019045626 | P20: =G20-G19 -> 0.0091436912 | Q20: =H20-H19 -> 0.0038250459
A21: 17 | B21: =Ej1a_PD!$I$164 -> 0.063804459 | C21: =Ej1a_PD!$I$165 -> 0.082950148 | D21: =Ej1a_PD!$I$166 -> 0.24313023 | E21: =Ej1a_PD!$I$167 -> 0.40258921 | F21: =Ej1a_PD!$I$168 -> 0.70350712 | G21: =Ej1a_PD!$I$169 -> 0.88998553 | H21: =Ej1a_PD!$I$170 -> 0.9631315 | J21: 17 | K21: =B21-B20 -> 0.0097545646 | L21: =C21-C20 -> 0.01080949 | M21: =D21-D20 -> 0.017484682 | N21: =E21-E20 -> 0.01914558 | O21: =F21-F20 -> 0.01657649 | P21: =G21-G20 -> 0.0077785352 | Q21: =H21-H20 -> 0.003199368
A22: 18 | B22: =Ej1a_PD!$I$174 -> 0.074029247 | C22: =Ej1a_PD!$I$175 -> 0.094059455 | D22: =Ej1a_PD!$I$176 -> 0.25967811 | E22: =Ej1a_PD!$I$177 -> 0.42013298 | F22: =Ej1a_PD!$I$178 -> 0.71799601 | G22: =Ej1a_PD!$I$179 -> 0.89664422 | H22: =Ej1a_PD!$I$180 -> 0.96582722 | J22: 18 | K22: =B22-B21 -> 0.010224789 | L22: =C22-C21 -> 0.011109307 | M22: =D22-D21 -> 0.016547884 | N22: =E22-E21 -> 0.017543769 | O22: =F22-F21 -> 0.014488897 | P22: =G22-G21 -> 0.0066586889 | Q22: =H22-H21 -> 0.0026957214
A23: 19 | B23: =Ej1a_PD!$I$184 -> 0.084641473 | C23: =Ej1a_PD!$I$185 -> 0.10539919 | D23: =Ej1a_PD!$I$186 -> 0.27534858 | E23: =Ej1a_PD!$I$187 -> 0.43624857 | F23: =Ej1a_PD!$I$188 -> 0.7307183 | G23: =Ej1a_PD!$I$189 -> 0.90237924 | H23: =Ej1a_PD!$I$190 -> 0.96811439 | J23: 19 | K23: =B23-B22 -> 0.010612226 | L23: =C23-C22 -> 0.011339739 | M23: =D23-D22 -> 0.015670472 | N23: =E23-E22 -> 0.016115591 | O23: =F23-F22 -> 0.012722282 | P23: =G23-G22 -> 0.0057350212 | Q23: =H23-H22 -> 0.0022871731
A24: 20 | B24: =Ej1a_PD!$I$194 -> 0.095566216 | C24: =Ej1a_PD!$I$195 -> 0.11690934 | D24: =Ej1a_PD!$I$196 -> 0.29020873 | E24: =Ej1a_PD!$I$197 -> 0.45109814 | F24: =Ej1a_PD!$I$198 -> 0.74194374 | G24: =Ej1a_PD!$I$199 -> 0.90734863 | H24: =Ej1a_PD!$I$200 -> 0.97006788 | J24: 20 | K24: =B24-B23 -> 0.010924743 | L24: =C24-C23 -> 0.011510141 | M24: =D24-D23 -> 0.014860148 | N24: =E24-E23 -> 0.014849572 | O24: =F24-F23 -> 0.011225442 | P24: =G24-G23 -> 0.0049693882 | Q24: =H24-H23 -> 0.0019534815
A25: 21 | B25: =Ej1a_PD!$I$204 -> 0.10673661 | C25: =Ej1a_PD!$I$205 -> 0.12853826 | D25: =Ej1a_PD!$I$206 -> 0.30432779 | E25: =Ej1a_PD!$I$207 -> 0.46483004 | F25: =Ej1a_PD!$I$208 -> 0.75189909 | G25: =Ej1a_PD!$I$209 -> 0.91168054 | H25: =Ej1a_PD!$I$210 -> 0.97174713 | J25: 21 | K25: =B25-B24 -> 0.011170392 | L25: =C25-C24 -> 0.011628928 | M25: =D25-D24 -> 0.014119055 | N25: =E25-E24 -> 0.013731896 | O25: =F25-F24 -> 0.0099553482 | P25: =G25-G24 -> 0.0043319085 | Q25: =H25-H24 -> 0.0016792525
A26: 22 | B26: =Ej1a_PD!$I$214 -> 0.11809363 | C26: =Ej1a_PD!$I$215 -> 0.14024182 | D26: =Ej1a_PD!$I$216 -> 0.31777355 | E26: =Ej1a_PD!$I$217 -> 0.47757794 | F26: =Ej1a_PD!$I$218 -> 0.76077503 | G26: =Ej1a_PD!$I$219 -> 0.91547951 | H26: =Ej1a_PD!$I$220 -> 0.97319978 | J26: 22 | K26: =B26-B25 -> 0.011357022 | L26: =C26-C25 -> 0.01170356 | M26: =D26-D25 -> 0.013445761 | N26: =E26-E25 -> 0.0127479 | O26: =F26-F25 -> 0.0088759464 | P26: =G26-G25 -> 0.0037989749 | Q26: =H26-H25 -> 0.0014526489
A27: 23 | B27: =Ej1a_PD!$I$224 -> 0.12958566 | C27: =Ej1a_PD!$I$225 -> 0.15198242 | D27: =Ej1a_PD!$I$226 -> 0.33061021 | E27: =Ej1a_PD!$I$227 -> 0.48946096 | F27: =Ej1a_PD!$I$228 -> 0.76873209 | G27: =Ej1a_PD!$I$229 -> 0.9188313 | H27: =Ej1a_PD!$I$230 -> 0.97446425 | J27: 23 | K27: =B27-B26 -> 0.011492029 | L27: =C27-C26 -> 0.011740594 | M27: =D27-D26 -> 0.01283666 | N27: =E27-E26 -> 0.011883021 | O27: =F27-F26 -> 0.0079570564 | P27: =G27-G26 -> 0.003351789 | Q27: =H27-H26 -> 0.0012644744
A28: 24 | B28: =Ej1a_PD!$I$234 -> 0.14116789 | C28: =Ej1a_PD!$I$235 -> 0.16372816 | D28: =Ej1a_PD!$I$236 -> 0.34289715 | E28: =Ej1a_PD!$I$237 -> 0.50058434 | F28: =Ej1a_PD!$I$238 -> 0.7759055 | G28: =Ej1a_PD!$I$239 -> 0.92180657 | H28: =Ej1a_PD!$I$240 -> 0.97557177 | J28: 24 | K28: =B28-B27 -> 0.011582227 | L28: =C28-C27 -> 0.011745744 | M28: =D28-D27 -> 0.012286939 | N28: =E28-E27 -> 0.011123375 | O28: =F28-F27 -> 0.0071734152 | P28: =G28-G27 -> 0.0029752718 | Q28: =H28-H27 -> 0.0011075164
A29: 25 | B29: =Ej1a_PD!$I$244 -> 0.15280167 | C29: =Ej1a_PD!$I$245 -> 0.17545213 | D29: =Ej1a_PD!$I$246 -> 0.35468839 | E29: =Ej1a_PD!$I$247 -> 0.51104042 | F29: =Ej1a_PD!$I$248 -> 0.78240936 | G29: =Ej1a_PD!$I$249 -> 0.92446382 | H29: =Ej1a_PD!$I$250 -> 0.97654784 | J29: 25 | K29: =B29-B28 -> 0.011633786 | L29: =C29-C28 -> 0.011723967 | M29: =D29-D28 -> 0.011791245 | N29: =E29-E28 -> 0.010456083 | O29: =F29-F28 -> 0.00650386 | P29: =G29-G28 -> 0.0026572458 | Q29: =H29-H28 -> 0.00097606764
A32: Comentario: en los ratings bajos (Caa-C, B) la PD marginal es maxima el primer/segundo ano y decrece desde ahi;
A33: en los intermedios (Baa, Ba) aparece una joroba a medio plazo; en los altos (Aaa, Aa) crece durante los 25 anos.

Sheet Ej1b_Cohorte
A1: Ejercicio 1.b - Cohorte de 5002 companias
A3: Rating | B3: N companias | C3: Peso w_i | D3: Peso acumulado
A4: Aaa | B4: 136 | C4: =B4/$B$11 -> 0.027189124 | D4: =SUM($C$4:C4) -> 0.027189124
A5: Aa | B5: 694 | C5: =B5/$B$11 -> 0.1387445 | D5: =SUM($C$4:C5) -> 0.16593363
A6: A | B6: 1298 | C6: =B6/$B$11 -> 0.2594962 | D6: =SUM($C$4:C6) -> 0.42542983
A7: Baa | B7: 1175 | C7: =B7/$B$11 -> 0.23490604 | D7: =SUM($C$4:C7) -> 0.66033587
A8: Ba | B8: 578 | C8: =B8/$B$11 -> 0.11555378 | D8: =SUM($C$4:C8) -> 0.77588964
A9: B | B9: 817 | C9: =B9/$B$11 -> 0.16333467 | D9: =SUM($C$4:C9) -> 0.93922431
A10: Caa-C | B10: 304 | C10: =B10/$B$11 -> 0.06077569 | D10: =SUM($C$4:C10) -> 1
A11: Total | B11: =SUM(B4:B10) -> 5002 | C11: =SUM(C4:C10) -> 1
A13: Pesos en horizontal (para SUMPRODUCT)
B14: Aaa | C14: Aa | D14: A | E14: Baa | F14: Ba | G14: B | H14: Caa-C
B15: =C4 -> 0.027189124 | C15: =C5 -> 0.1387445 | D15: =C6 -> 0.2594962 | E15: =C7 -> 0.23490604 | F15: =C8 -> 0.11555378 | G15: =C9 -> 0.16333467 | H15: =C10 -> 0.06077569
A18: Ano | B18: Prop. que hace default exactamente en el ano n | C18: Numero esperado de companias | D18: Prop. acumulada | E18: Numero esperado acumulado
A19: 1 | B19: =SUMPRODUCT($B$15:$H$15,Ej1a_Res!K5:Q5) -> 0.022614474 | C19: =B19*$B$11 -> 113.1176 | D19: =SUMPRODUCT($B$15:$H$15,Ej1a_Res!B5:H5) -> 0.022614474 | E19: =D19*$B$11 -> 113.1176
A20: 2 | B20: =SUMPRODUCT($B$15:$H$15,Ej1a_Res!K6:Q6) -> 0.041711394 | C20: =B20*$B$11 -> 208.64039 | D20: =SUMPRODUCT($B$15:$H$15,Ej1a_Res!B6:H6) -> 0.064325868 | E20: =D20*$B$11 -> 321.75799
A21: 3 | B21: =SUMPRODUCT($B$15:$H$15,Ej1a_Res!K7:Q7) -> 0.040324731 | C21: =B21*$B$11 -> 201.7043 | D21: =SUMPRODUCT($B$15:$H$15,Ej1a_Res!B7:H7) -> 0.1046506 | E21: =D21*$B$11 -> 523.4623
A22: 4 | B22: =SUMPRODUCT($B$15:$H$15,Ej1a_Res!K8:Q8) -> 0.038064252 | C22: =B22*$B$11 -> 190.39739 | D22: =SUMPRODUCT($B$15:$H$15,Ej1a_Res!B8:H8) -> 0.14271485 | E22: =D22*$B$11 -> 713.85968
A23: 5 | B23: =SUMPRODUCT($B$15:$H$15,Ej1a_Res!K9:Q9) -> 0.036034197 | C23: =B23*$B$11 -> 180.24305 | D23: =SUMPRODUCT($B$15:$H$15,Ej1a_Res!B9:H9) -> 0.17874905 | E23: =D23*$B$11 -> 894.10273
A24: 6 | B24: =SUMPRODUCT($B$15:$H$15,Ej1a_Res!K10:Q10) -> 0.034018666 | C24: =B24*$B$11 -> 170.16137 | D24: =SUMPRODUCT($B$15:$H$15,Ej1a_Res!B10:H10) -> 0.21276771 | E24: =D24*$B$11 -> 1064.2641
A25: 7 | B25: =SUMPRODUCT($B$15:$H$15,Ej1a_Res!K11:Q11) -> 0.031917168 | C25: =B25*$B$11 -> 159.64967 | D25: =SUMPRODUCT($B$15:$H$15,Ej1a_Res!B11:H11) -> 0.24468488 | E25: =D25*$B$11 -> 1223.9138
A26: 8 | B26: =SUMPRODUCT($B$15:$H$15,Ej1a_Res!K12:Q12) -> 0.029743459 | C26: =B26*$B$11 -> 148.77678 | D26: =SUMPRODUCT($B$15:$H$15,Ej1a_Res!B12:H12) -> 0.27442834 | E26: =D26*$B$11 -> 1372.6906
A27: 9 | B27: =SUMPRODUCT($B$15:$H$15,Ej1a_Res!K13:Q13) -> 0.02755441 | C27: =B27*$B$11 -> 137.82716 | D27: =SUMPRODUCT($B$15:$H$15,Ej1a_Res!B13:H13) -> 0.30198275 | E27: =D27*$B$11 -> 1510.5177
A28: 10 | B28: =SUMPRODUCT($B$15:$H$15,Ej1a_Res!K14:Q14) -> 0.025411292 | C28: =B28*$B$11 -> 127.10728 | D28: =SUMPRODUCT($B$15:$H$15,Ej1a_Res!B14:H14) -> 0.32739404 | E28: =D28*$B$11 -> 1637.625
A29: 11 | B29: =SUMPRODUCT($B$15:$H$15,Ej1a_Res!K15:Q15) -> 0.023364085 | C29: =B29*$B$11 -> 116.86716 | D29: =SUMPRODUCT($B$15:$H$15,Ej1a_Res!B15:H15) -> 0.35075813 | E29: =D29*$B$11 -> 1754.4921
A30: 12 | B30: =SUMPRODUCT($B$15:$H$15,Ej1a_Res!K16:Q16) -> 0.021447372 | C30: =B30*$B$11 -> 107.27975 | D30: =SUMPRODUCT($B$15:$H$15,Ej1a_Res!B16:H16) -> 0.3722055 | E30: =D30*$B$11 -> 1861.7719
... A43: 25 | B43: =SUMPRODUCT($B$15:$H$15,Ej1a_Res!K29:Q29) -> 0.0087038157 | C43: =B43*$B$11 -> 43.536486 | D43: =SUMPRODUCT($B$15:$H$15,Ej1a_Res!B29:H29) -> 0.54134205 | E43: =D43*$B$11 -> 2707.7929

Sheet Ej1c_25anos
A1: Ejercicio 1.c - Distribucion de rating a 25 anos y comprobacion por simulacion
A3: Distribucion teorica a 25 anos = fila correspondiente de P^25
A4: Origen | B4: Aaa | C4: Aa | D4: A | E4: Baa | F4: Ba | G4: B | H4: Caa-C | I4: Default
A5: Aaa | B5: =Ej1a_PD!B244 -> 0.37527278 | C5: =Ej1a_PD!C244 -> 0.17821506 | D5: =Ej1a_PD!D244 -> 0.11925155 | E5: =Ej1a_PD!E244 -> 0.057768061 | F5: =Ej1a_PD!F244 -> 0.055144054 | G5: =Ej1a_PD!G244 -> 0.029272378 | H5: =Ej1a_PD!H244 -> 0.032274442 | I5: =Ej1a_PD!I244 -> 0.15280167
A6: Aa | B6: =Ej1a_PD!B245 -> 0.36342017 | C6: =Ej1a_PD!C245 -> 0.17284891 | D6: =Ej1a_PD!D245 -> 0.11610271 | E6: =Ej1a_PD!E245 -> 0.056413795 | F6: =Ej1a_PD!F245 -> 0.054332205 | G6: =Ej1a_PD!G245 -> 0.029075011 | H6: =Ej1a_PD!H245 -> 0.032355076 | I6: =Ej1a_PD!I245 -> 0.17545213
A7: A | B7: =Ej1a_PD!B246 -> 0.27272973 | C7: =Ej1a_PD!C246 -> 0.13138607 | D7: =Ej1a_PD!D246 -> 0.091075288 | E7: =Ej1a_PD!E246 -> 0.045349722 | F7: =Ej1a_PD!F246 -> 0.046773601 | G7: =Ej1a_PD!G246 -> 0.026539577 | H7: =Ej1a_PD!H246 -> 0.031457622 | I7: =Ej1a_PD!I246 -> 0.35468839
A8: Baa | B8: =Ej1a_PD!B247 -> 0.20008236 | C8: =Ej1a_PD!C247 -> 0.097333247 | D8: =Ej1a_PD!D247 -> 0.069067387 | E8: =Ej1a_PD!E247 -> 0.035002927 | F8: =Ej1a_PD!F247 -> 0.037821634 | G8: =Ej1a_PD!G247 -> 0.022268398 | H8: =Ej1a_PD!H247 -> 0.027383623 | I8: =Ej1a_PD!I247 -> 0.51104042
A9: Ba | B9: =Ej1a_PD!B248 -> 0.081363082 | C9: =Ej1a_PD!C248 -> 0.04067306 | D9: =Ej1a_PD!D248 -> 0.030721638 | E9: =Ej1a_PD!E248 -> 0.016280522 | F9: =Ej1a_PD!F248 -> 0.019602106 | G9: =Ej1a_PD!G248 -> 0.012478258 | H9: =Ej1a_PD!H248 -> 0.016471971 | I9: =Ej1a_PD!I248 -> 0.78240936
A10: B | B10: =Ej1a_PD!B249 -> 0.026676374 | C10: =Ej1a_PD!C249 -> 0.013566352 | D10: =Ej1a_PD!D249 -> 0.010638537 | E10: =Ej1a_PD!E249 -> 0.0057826544 | F10: =Ej1a_PD!F249 -> 0.0073676002 | G10: =Ej1a_PD!G249 -> 0.0048697879 | H10: =Ej1a_PD!H249 -> 0.0066348766 | I10: =Ej1a_PD!I249 -> 0.92446382
A11: Caa-C | B11: =Ej1a_PD!B250 -> 0.0076949296 | C11: =Ej1a_PD!C250 -> 0.004003917 | D11: =Ej1a_PD!D250 -> 0.0032914751 | E11: =Ej1a_PD!E250 -> 0.0018434935 | F11: =Ej1a_PD!F250 -> 0.002497956 | G11: =Ej1a_PD!G250 -> 0.0017143208 | H11: =Ej1a_PD!H250 -> 0.002406072 | I11: =Ej1a_PD!I250 -> 0.97654784
A12: Cohorte | B12: =SUMPRODUCT(Ej1b_Cohorte!$C$4:$C$10,B5:B11) -> 0.19262543 | C12: =SUMPRODUCT(Ej1b_Cohorte!$C$4:$C$10,C5:C11) -> 0.092944823 | D12: =SUMPRODUCT(Ej1b_Cohorte!$C$4:$C$10,D5:D11) -> 0.06469668 | E12: =SUMPRODUCT(Ej1b_Cohorte!$C$4:$C$10,E5:E11) -> 0.03232607 | F12: =SUMPRODUCT(Ej1b_Cohorte!$C$4:$C$10,F5:F11) -> 0.033680012 | G12: =SUMPRODUCT(Ej1b_Cohorte!$C$4:$C$10,G5:G11) -> 0.019289293 | H12: =SUMPRODUCT(Ej1b_Cohorte!$C$4:$C$10,H5:H11) -> 0.023095649 | I12: =SUMPRODUCT(Ej1b_Cohorte!$C$4:$C$10,I5:I11) -> 0.54134205
A15: SIMULACION (2000 companias elegidas al azar en la cohorte, 25 transiciones cada una)
A16: Pulsa F9 para volver a sortear (al abrir el libro, pulsalo un par de veces). El estado 8 (Default) es absorbente.
A18: Estado final | B18: Frecuencia simulada | C18: Probabilidad teorica
A19: Aaa | B19: =COUNTIF($AB$31:$AB$2030,1)/2000 -> 0.1925 | C19: =B12 -> 0.19262543
A20: Aa | B20: =COUNTIF($AB$31:$AB$2030,2)/2000 -> 0.0885 | C20: =C12 -> 0.092944823
A21: A | B21: =COUNTIF($AB$31:$AB$2030,3)/2000 -> 0.0575 | C21: =D12 -> 0.06469668
A22: Baa | B22: =COUNTIF($AB$31:$AB$2030,4)/2000 -> 0.0295 | C22: =E12 -> 0.03232607
A23: Ba | B23: =COUNTIF($AB$31:$AB$2030,5)/2000 -> 0.034 | C23: =F12 -> 0.033680012
A24: B | B24: =COUNTIF($AB$31:$AB$2030,6)/2000 -> 0.019 | C24: =G12 -> 0.019289293
A25: Caa-C | B25: =COUNTIF($AB$31:$AB$2030,7)/2000 -> 0.022 | C25: =H12 -> 0.023095649
A26: Default | B26: =COUNTIF($AB$31:$AB$2030,8)/2000 -> 0.557 | C26: =I12 -> 0.54134205
A28: Bloque de simulacion: A = estado inicial (sorteado con los pesos de la cohorte); B..Z = estado tras cada ano; AB = estado final
A30: ini | B30: ano 1 | C30: ano 2 | D30: ano 3 | E30: ano 4 | F30: ano 5 | G30: ano 6 | H30: ano 7 | I30: ano 8 | J30: ano 9 | K30: ano 10 | L30: ano 11 | M30: ano 12 | N30: ano 13 | O30: ano 14 | P30: ano 15 | Q30: ano 16 | R30: ano 17 | S30: ano 18 | T30: ano 19 | U30: ano 20 | V30: ano 21 | W30: ano 22 | X30: ano 23 | Y30: ano 24 | Z30: ano 25 | AB30: final
A31: =IFERROR(MATCH(RAND(),Ej1b_Cohorte!$D$4:$D$10,1)+1,1) -> 5 | B31: =IF(A31=8,8,IFERROR(MATCH(RAND(),INDEX(MATRIZ_CUM,A31,0),1)+1,1)) -> 4 | C31: =IF(B31=8,8,IFERROR(MATCH(RAND(),INDEX(MATRIZ_CUM,B31,0),1)+1,1)) -> 5 | D31: =IF(C31=8,8,IFERROR(MATCH(RAND(),INDEX(MATRIZ_CUM,C31,0),1)+1,1)) -> 4 | E31: =IF(D31=8,8,IFERROR(MATCH(RAND(),INDEX(MATRIZ_CUM,D31,0),1)+1,1)) -> 5 | F31: =IF(E31=8,8,IFERROR(MATCH(RAND(),INDEX(MATRIZ_CUM,E31,0),1)+1,1)) -> 5 | G31: =IF(F31=8,8,IFERROR(MATCH(RAND(),INDEX(MATRIZ_CUM,F31,0),1)+1,1)) -> 5 | H31: =IF(G31=8,8,IFERROR(MATCH(RAND(),INDEX(MATRIZ_CUM,G31,0),1)+1,1)) -> 6 | I31: =IF(H31=8,8,IFERROR(MATCH(RAND(),INDEX(MATRIZ_CUM,H31,0),1)+1,1)) -> 6 | ... Z31: =IF(Y31=8,8,IFERROR(MATCH(RAND(),INDEX(MATRIZ_CUM,Y31,0),1)+1,1)) -> 8 | AB31: =Z31 -> 8
A32: =IFERROR(MATCH(RAND(),Ej1b_Cohorte!$D$4:$D$10,1)+1,1) -> 4 | B32: =IF(A32=8,8,IFERROR(MATCH(RAND(),INDEX(MATRIZ_CUM,A32,0),1)+1,1)) -> 4 | C32: =IF(B32=8,8,IFERROR(MATCH(RAND(),INDEX(MATRIZ_CUM,B32,0),1)+1,1)) -> 3 | D32: =IF(C32=8,8,IFERROR(MATCH(RAND(),INDEX(MATRIZ_CUM,C32,0),1)+1,1)) -> 3 | E32: =IF(D32=8,8,IFERROR(MATCH(RAND(),INDEX(MATRIZ_CUM,D32,0),1)+1,1)) -> 3 | F32: =IF(E32=8,8,IFERROR(MATCH(RAND(),INDEX(MATRIZ_CUM,E32,0),1)+1,1)) -> 3 | G32: =IF(F32=8,8,IFERROR(MATCH(RAND(),INDEX(MATRIZ_CUM,F32,0),1)+1,1)) -> 3 | H32: =IF(G32=8,8,IFERROR(MATCH(RAND(),INDEX(MATRIZ_CUM,G32,0),1)+1,1)) -> 5 | I32: =IF(H32=8,8,IFERROR(MATCH(RAND(),INDEX(MATRIZ_CUM,H32,0),1)+1,1)) -> 6 | ... Z32: =IF(Y32=8,8,IFERROR(MATCH(RAND(),INDEX(MATRIZ_CUM,Y32,0),1)+1,1)) -> 8 | AB32: =Z32 -> 8
A33: =IFERROR(MATCH(RAND(),Ej1b_Cohorte!$D$4:$D$10,1)+1,1) -> 2 | B33: =IF(A33=8,8,IFERROR(MATCH(RAND(),INDEX(MATRIZ_CUM,A33,0),1)+1,1)) -> 2 | C33: =IF(B33=8,8,IFERROR(MATCH(RAND(),INDEX(MATRIZ_CUM,B33,0),1)+1,1)) -> 2 | D33: =IF(C33=8,8,IFERROR(MATCH(RAND(),INDEX(MATRIZ_CUM,C33,0),1)+1,1)) -> 2 | E33: =IF(D33=8,8,IFERROR(MATCH(RAND(),INDEX(MATRIZ_CUM,D33,0),1)+1,1)) -> 1 | F33: =IF(E33=8,8,IFERROR(MATCH(RAND(),INDEX(MATRIZ_CUM,E33,0),1)+1,1)) -> 1 | G33: =IF(F33=8,8,IFERROR(MATCH(RAND(),INDEX(MATRIZ_CUM,F33,0),1)+1,1)) -> 1 | H33: =IF(G33=8,8,IFERROR(MATCH(RAND(),INDEX(MATRIZ_CUM,G33,0),1)+1,1)) -> 1 | I33: =IF(H33=8,8,IFERROR(MATCH(RAND(),INDEX(MATRIZ_CUM,H33,0),1)+1,1)) -> 1 | ... Z33: =IF(Y33=8,8,IFERROR(MATCH(RAND(),INDEX(MATRIZ_CUM,Y33,0),1)+1,1)) -> 1 | AB33: =Z33 -> 1
A34: =IFERROR(MATCH(RAND(),Ej1b_Cohorte!$D$4:$D$10,1)+1,1) -> 6 | B34: =IF(A34=8,8,IFERROR(MATCH(RAND(),INDEX(MATRIZ_CUM,A34,0),1)+1,1)) -> 7 | C34: =IF(B34=8,8,IFERROR(MATCH(RAND(),INDEX(MATRIZ_CUM,B34,0),1)+1,1)) -> 6 | D34: =IF(C34=8,8,IFERROR(MATCH(RAND(),INDEX(MATRIZ_CUM,C34,0),1)+1,1)) -> 7 | E34: =IF(D34=8,8,IFERROR(MATCH(RAND(),INDEX(MATRIZ_CUM,D34,0),1)+1,1)) -> 8 | F34: =IF(E34=8,8,IFERROR(MATCH(RAND(),INDEX(MATRIZ_CUM,E34,0),1)+1,1)) -> 8 | G34: =IF(F34=8,8,IFERROR(MATCH(RAND(),INDEX(MATRIZ_CUM,F34,0),1)+1,1)) -> 8 | H34: =IF(G34=8,8,IFERROR(MATCH(RAND(),INDEX(MATRIZ_CUM,G34,0),1)+1,1)) -> 8 | I34: =IF(H34=8,8,IFERROR(MATCH(RAND(),INDEX(MATRIZ_CUM,H34,0),1)+1,1)) -> 8 | ... Z34: =IF(Y34=8,8,IFERROR(MATCH(RAND(),INDEX(MATRIZ_CUM,Y34,0),1)+1,1)) -> 8 | AB34: =Z34 -> 8
A35: =IFERROR(MATCH(RAND(),Ej1b_Cohorte!$D$4:$D$10,1)+1,1) -> 3 | B35: =IF(A35=8,8,IFERROR(MATCH(RAND(),INDEX(MATRIZ_CUM,A35,0),1)+1,1)) -> 3 | C35: =IF(B35=8,8,IFERROR(MATCH(RAND(),INDEX(MATRIZ_CUM,B35,0),1)+1,1)) -> 2 | D35: =IF(C35=8,8,IFERROR(MATCH(RAND(),INDEX(MATRIZ_CUM,C35,0),1)+1,1)) -> 2 | E35: =IF(D35=8,8,IFERROR(MATCH(RAND(),INDEX(MATRIZ_CUM,D35,0),1)+1,1)) -> 2 | F35: =IF(E35=8,8,IFERROR(MATCH(RAND(),INDEX(MATRIZ_CUM,E35,0),1)+1,1)) -> 3 | G35: =IF(F35=8,8,IFERROR(MATCH(RAND(),INDEX(MATRIZ_CUM,F35,0),1)+1,1)) -> 3 | H35: =IF(G35=8,8,IFERROR(MATCH(RAND(),INDEX(MATRIZ_CUM,G35,0),1)+1,1)) -> 3 | I35: =IF(H35=8,8,IFERROR(MATCH(RAND(),INDEX(MATRIZ_CUM,H35,0),1)+1,1)) -> 3 | ... Z35: =IF(Y35=8,8,IFERROR(MATCH(RAND(),INDEX(MATRIZ_CUM,Y35,0),1)+1,1)) -> 2 | AB35: =Z35 -> 2
A36: =IFERROR(MATCH(RAND(),Ej1b_Cohorte!$D$4:$D$10,1)+1,1) -> 6 | B36: =IF(A36=8,8,IFERROR(MATCH(RAND(),INDEX(MATRIZ_CUM,A36,0),1)+1,1)) -> 7 | C36: =IF(B36=8,8,IFERROR(MATCH(RAND(),INDEX(MATRIZ_CUM,B36,0),1)+1,1)) -> 8 | D36: =IF(C36=8,8,IFERROR(MATCH(RAND(),INDEX(MATRIZ_CUM,C36,0),1)+1,1)) -> 8 | E36: =IF(D36=8,8,IFERROR(MATCH(RAND(),INDEX(MATRIZ_CUM,D36,0),1)+1,1)) -> 8 | F36: =IF(E36=8,8,IFERROR(MATCH(RAND(),INDEX(MATRIZ_CUM,E36,0),1)+1,1)) -> 8 | G36: =IF(F36=8,8,IFERROR(MATCH(RAND(),INDEX(MATRIZ_CUM,F36,0),1)+1,1)) -> 8 | H36: =IF(G36=8,8,IFERROR(MATCH(RAND(),INDEX(MATRIZ_CUM,G36,0),1)+1,1)) -> 8 | I36: =IF(H36=8,8,IFERROR(MATCH(RAND(),INDEX(MATRIZ_CUM,H36,0),1)+1,1)) -> 8 | ... Z36: =IF(Y36=8,8,IFERROR(MATCH(RAND(),INDEX(MATRIZ_CUM,Y36,0),1)+1,1)) -> 8 | AB36: =Z36 -> 8
A37: =IFERROR(MATCH(RAND(),Ej1b_Cohorte!$D$4:$D$10,1)+1,1) -> 2 | B37: =IF(A37=8,8,IFERROR(MATCH(RAND(),INDEX(MATRIZ_CUM,A37,0),1)+1,1)) -> 2 | C37: =IF(B37=8,8,IFERROR(MATCH(RAND(),INDEX(MATRIZ_CUM,B37,0),1)+1,1)) -> 1 | D37: =IF(C37=8,8,IFERROR(MATCH(RAND(),INDEX(MATRIZ_CUM,C37,0),1)+1,1)) -> 1 | E37: =IF(D37=8,8,IFERROR(MATCH(RAND(),INDEX(MATRIZ_CUM,D37,0),1)+1,1)) -> 1 | F37: =IF(E37=8,8,IFERROR(MATCH(RAND(),INDEX(MATRIZ_CUM,E37,0),1)+1,1)) -> 2 | G37: =IF(F37=8,8,IFERROR(MATCH(RAND(),INDEX(MATRIZ_CUM,F37,0),1)+1,1)) -> 2 | H37: =IF(G37=8,8,IFERROR(MATCH(RAND(),INDEX(MATRIZ_CUM,G37,0),1)+1,1)) -> 4 | I37: =IF(H37=8,8,IFERROR(MATCH(RAND(),INDEX(MATRIZ_CUM,H37,0),1)+1,1)) -> 5 | ... Z37: =IF(Y37=8,8,IFERROR(MATCH(RAND(),INDEX(MATRIZ_CUM,Y37,0),1)+1,1)) -> 3 | AB37: =Z37 -> 3
A38: =IFERROR(MATCH(RAND(),Ej1b_Cohorte!$D$4:$D$10,1)+1,1) -> 3 | B38: =IF(A38=8,8,IFERROR(MATCH(RAND(),INDEX(MATRIZ_CUM,A38,0),1)+1,1)) -> 2 | C38: =IF(B38=8,8,IFERROR(MATCH(RAND(),INDEX(MATRIZ_CUM,B38,0),1)+1,1)) -> 2 | D38: =IF(C38=8,8,IFERROR(MATCH(RAND(),INDEX(MATRIZ_CUM,C38,0),1)+1,1)) -> 2 | E38: =IF(D38=8,8,IFERROR(MATCH(RAND(),INDEX(MATRIZ_CUM,D38,0),1)+1,1)) -> 1 | F38: =IF(E38=8,8,IFERROR(MATCH(RAND(),INDEX(MATRIZ_CUM,E38,0),1)+1,1)) -> 1 | G38: =IF(F38=8,8,IFERROR(MATCH(RAND(),INDEX(MATRIZ_CUM,F38,0),1)+1,1)) -> 1 | H38: =IF(G38=8,8,IFERROR(MATCH(RAND(),INDEX(MATRIZ_CUM,G38,0),1)+1,1)) -> 1 | I38: =IF(H38=8,8,IFERROR(MATCH(RAND(),INDEX(MATRIZ_CUM,H38,0),1)+1,1)) -> 1 | ... Z38: =IF(Y38=8,8,IFERROR(MATCH(RAND(),INDEX(MATRIZ_CUM,Y38,0),1)+1,1)) -> 1 | AB38: =Z38 -> 1
A39: =IFERROR(MATCH(RAND(),Ej1b_Cohorte!$D$4:$D$10,1)+1,1) -> 5 | B39: =IF(A39=8,8,IFERROR(MATCH(RAND(),INDEX(MATRIZ_CUM,A39,0),1)+1,1)) -> 4 | C39: =IF(B39=8,8,IFERROR(MATCH(RAND(),INDEX(MATRIZ_CUM,B39,0),1)+1,1)) -> 5 | D39: =IF(C39=8,8,IFERROR(MATCH(RAND(),INDEX(MATRIZ_CUM,C39,0),1)+1,1)) -> 5 | E39: =IF(D39=8,8,IFERROR(MATCH(RAND(),INDEX(MATRIZ_CUM,D39,0),1)+1,1)) -> 5 | F39: =IF(E39=8,8,IFERROR(MATCH(RAND(),INDEX(MATRIZ_CUM,E39,0),1)+1,1)) -> 6 | G39: =IF(F39=8,8,IFERROR(MATCH(RAND(),INDEX(MATRIZ_CUM,F39,0),1)+1,1)) -> 5 | H39: =IF(G39=8,8,IFERROR(MATCH(RAND(),INDEX(MATRIZ_CUM,G39,0),1)+1,1)) -> 5 | I39: =IF(H39=8,8,IFERROR(MATCH(RAND(),INDEX(MATRIZ_CUM,H39,0),1)+1,1)) -> 5 | ... Z39: =IF(Y39=8,8,IFERROR(MATCH(RAND(),INDEX(MATRIZ_CUM,Y39,0),1)+1,1)) -> 8 | AB39: =Z39 -> 8
A40: =IFERROR(MATCH(RAND(),Ej1b_Cohorte!$D$4:$D$10,1)+1,1) -> 6 | B40: =IF(A40=8,8,IFERROR(MATCH(RAND(),INDEX(MATRIZ_CUM,A40,0),1)+1,1)) -> 7 | C40: =IF(B40=8,8,IFERROR(MATCH(RAND(),INDEX(MATRIZ_CUM,B40,0),1)+1,1)) -> 7 | D40: =IF(C40=8,8,IFERROR(MATCH(RAND(),INDEX(MATRIZ_CUM,C40,0),1)+1,1)) -> 7 | E40: =IF(D40=8,8,IFERROR(MATCH(RAND(),INDEX(MATRIZ_CUM,D40,0),1)+1,1)) -> 8 | F40: =IF(E40=8,8,IFERROR(MATCH(RAND(),INDEX(MATRIZ_CUM,E40,0),1)+1,1)) -> 8 | G40: =IF(F40=8,8,IFERROR(MATCH(RAND(),INDEX(MATRIZ_CUM,F40,0),1)+1,1)) -> 8 | H40: =IF(G40=8,8,IFERROR(MATCH(RAND(),INDEX(MATRIZ_CUM,G40,0),1)+1,1)) -> 8 | I40: =IF(H40=8,8,IFERROR(MATCH(RAND(),INDEX(MATRIZ_CUM,H40,0),1)+1,1)) -> 8 | ... Z40: =IF(Y40=8,8,IFERROR(MATCH(RAND(),INDEX(MATRIZ_CUM,Y40,0),1)+1,1)) -> 8 | AB40: =Z40 -> 8
A41: =IFERROR(MATCH(RAND(),Ej1b_Cohorte!$D$4:$D$10,1)+1,1) -> 2 | B41: =IF(A41=8,8,IFERROR(MATCH(RAND(),INDEX(MATRIZ_CUM,A41,0),1)+1,1)) -> 1 | C41: =IF(B41=8,8,IFERROR(MATCH(RAND(),INDEX(MATRIZ_CUM,B41,0),1)+1,1)) -> 1 | D41: =IF(C41=8,8,IFERROR(MATCH(RAND(),INDEX(MATRIZ_CUM,C41,0),1)+1,1)) -> 1 | E41: =IF(D41=8,8,IFERROR(MATCH(RAND(),INDEX(MATRIZ_CUM,D41,0),1)+1,1)) -> 1 | F41: =IF(E41=8,8,IFERROR(MATCH(RAND(),INDEX(MATRIZ_CUM,E41,0),1)+1,1)) -> 1 | G41: =IF(F41=8,8,IFERROR(MATCH(RAND(),INDEX(MATRIZ_CUM,F41,0),1)+1,1)) -> 1 | H41: =IF(G41=8,8,IFERROR(MATCH(RAND(),INDEX(MATRIZ_CUM,G41,0),1)+1,1)) -> 1 | I41: =IF(H41=8,8,IFERROR(MATCH(RAND(),INDEX(MATRIZ_CUM,H41,0),1)+1,1)) -> 1 | ... Z41: =IF(Y41=8,8,IFERROR(MATCH(RAND(),INDEX(MATRIZ_CUM,Y41,0),1)+1,1)) -> 2 | AB41: =Z41 -> 2
A42: =IFERROR(MATCH(RAND(),Ej1b_Cohorte!$D$4:$D$10,1)+1,1) -> 1 | B42: =IF(A42=8,8,IFERROR(MATCH(RAND(),INDEX(MATRIZ_CUM,A42,0),1)+1,1)) -> 1 | C42: =IF(B42=8,8,IFERROR(MATCH(RAND(),INDEX(MATRIZ_CUM,B42,0),1)+1,1)) -> 1 | D42: =IF(C42=8,8,IFERROR(MATCH(RAND(),INDEX(MATRIZ_CUM,C42,0),1)+1,1)) -> 1 | E42: =IF(D42=8,8,IFERROR(MATCH(RAND(),INDEX(MATRIZ_CUM,D42,0),1)+1,1)) -> 1 | F42: =IF(E42=8,8,IFERROR(MATCH(RAND(),INDEX(MATRIZ_CUM,E42,0),1)+1,1)) -> 1 | G42: =IF(F42=8,8,IFERROR(MATCH(RAND(),INDEX(MATRIZ_CUM,F42,0),1)+1,1)) -> 1 | H42: =IF(G42=8,8,IFERROR(MATCH(RAND(),INDEX(MATRIZ_CUM,G42,0),1)+1,1)) -> 1 | I42: =IF(H42=8,8,IFERROR(MATCH(RAND(),INDEX(MATRIZ_CUM,H42,0),1)+1,1)) -> 1 | ... Z42: =IF(Y42=8,8,IFERROR(MATCH(RAND(),INDEX(MATRIZ_CUM,Y42,0),1)+1,1)) -> 2 | AB42: =Z42 -> 2
... A2030: =IFERROR(MATCH(RAND(),Ej1b_Cohorte!$D$4:$D$10,1)+1,1) -> 2 | B2030: =IF(A2030=8,8,IFERROR(MATCH(RAND(),INDEX(MATRIZ_CUM,A2030,0),1)+1,1)) -> 1 | C2030: =IF(B2030=8,8,IFERROR(MATCH(RAND(),INDEX(MATRIZ_CUM,B2030,0),1)+1,1)) -> 1 | D2030: =IF(C2030=8,8,IFERROR(MATCH(RAND(),INDEX(MATRIZ_CUM,C2030,0),1)+1,1)) -> 1 | E2030: =IF(D2030=8,8,IFERROR(MATCH(RAND(),INDEX(MATRIZ_CUM,D2030,0),1)+1,1)) -> 2 | F2030: =IF(E2030=8,8,IFERROR(MATCH(RAND(),INDEX(MATRIZ_CUM,E2030,0),1)+1,1)) -> 2 | G2030: =IF(F2030=8,8,IFERROR(MATCH(RAND(),INDEX(MATRIZ_CUM,F2030,0),1)+1,1)) -> 1 | H2030: =IF(G2030=8,8,IFERROR(MATCH(RAND(),INDEX(MATRIZ_CUM,G2030,0),1)+1,1)) -> 1 | I2030: =IF(H2030=8,8,IFERROR(MATCH(RAND(),INDEX(MATRIZ_CUM,H2030,0),1)+1,1)) -> 1 | ... Z2030: =IF(Y2030=8,8,IFERROR(MATCH(RAND(),INDEX(MATRIZ_CUM,Y2030,0),1)+1,1)) -> 3 | AB2030: =Z2030 -> 3

Sheet Ej2c_Mt
A1: Ejercicio 2.c - Simulacion de M_t = ( Int_0^t s dW_s )^2 - t^3/3
A3: T | B3: 1 | G3: Comprobacion empirica de la distribucion de M_1
A4: n pasos | B4: 500 | G4: Var. discreta de N_1 | I4: =SUMPRODUCT(($B$8:$B$507)^2)*$B$5 -> 0.332334
A5: dt | B5: =B3/B4 -> 0.002 | G5: Var. exacta = T^3/3 | I5: =B3^3/3 -> 0.33333333
A7: k | B7: t_k | C7: dW_k | D7: N_k = Int_0^t s dW | E7: M_k | G7: N_1 (replica) | H7: M_1 = N_1^2 - T^3/3
A8: 0 | B8: 0 | C8: 0 | D8: 0 | E8: =D8^2-B8^3/3 -> 0 | G8: =_xlfn.NORM.S.INV(RAND())*SQRT($I$4) -> -0.051666801 | H8: =G8^2-$B$3^3/3 -> -0.33066388
A9: =A8+1 -> 1 | B9: =A9*$B$5 -> 0.002 | C9: =_xlfn.NORM.S.INV(RAND())*SQRT($B$5) -> -0.05149947 | D9: =D8+B8*C9 -> 0 | E9: =D9^2-B9^3/3 -> -2.6666667e-09 | G9: =_xlfn.NORM.S.INV(RAND())*SQRT($I$4) -> -0.36825148 | H9: =G9^2-$B$3^3/3 -> -0.19772418
A10: =A9+1 -> 2 | B10: =A10*$B$5 -> 0.004 | C10: =_xlfn.NORM.S.INV(RAND())*SQRT($B$5) -> 0.023759366 | D10: =D9+B9*C10 -> 4.7518731e-05 | E10: =D10^2-B10^3/3 -> -1.9075303e-08 | G10: =_xlfn.NORM.S.INV(RAND())*SQRT($I$4) -> -0.48444493 | H10: =G10^2-$B$3^3/3 -> -0.098646439 | J10: Estadistico | K10: Simulado | L10: Teorico
A11: =A10+1 -> 3 | B11: =A11*$B$5 -> 0.006 | C11: =_xlfn.NORM.S.INV(RAND())*SQRT($B$5) -> -0.0026888622 | D11: =D10+B10*C11 -> 3.6763282e-05 | E11: =D11^2-B11^3/3 -> -7.0648461e-08 | G11: =_xlfn.NORM.S.INV(RAND())*SQRT($I$4) -> -0.60323173 | H11: =G11^2-$B$3^3/3 -> 0.030555192 | J11: E(M_1) | K11: =AVERAGE(H8:H3007) -> 0.0029912338 | L11: =0 -> 0
A12: =A11+1 -> 4 | B12: =A12*$B$5 -> 0.008 | C12: =_xlfn.NORM.S.INV(RAND())*SQRT($B$5) -> -0.0019822975 | D12: =D11+B11*C12 -> 2.4869497e-05 | E12: =D12^2-B12^3/3 -> -1.7004817e-07 | G12: =_xlfn.NORM.S.INV(RAND())*SQRT($I$4) -> -0.40052685 | H12: =G12^2-$B$3^3/3 -> -0.17291158 | J12: V(M_1) | K12: =_xlfn.VAR.S(H8:H3007) -> 0.21750253 | L12: =2*B3^6/9 -> 0.22222222
A13: =A12+1 -> 5 | B13: =A13*$B$5 -> 0.01 | C13: =_xlfn.NORM.S.INV(RAND())*SQRT($B$5) -> -0.046280491 | D13: =D12+B12*C13 -> -0.00034537443 | E13: =D13^2-B13^3/3 -> -2.1404984e-07 | G13: =_xlfn.NORM.S.INV(RAND())*SQRT($I$4) -> -0.76448636 | H13: =G13^2-$B$3^3/3 -> 0.25110606 | J13: sd(M_1) | K13: =_xlfn.STDEV.S(H8:H3007) -> 0.46637167 | L13: =SQRT(2*B3^6/9) -> 0.47140452
A14: =A13+1 -> 6 | B14: =A14*$B$5 -> 0.012 | C14: =_xlfn.NORM.S.INV(RAND())*SQRT($B$5) -> 0.0010273851 | D14: =D13+B13*C14 -> -0.00033510058 | E14: =D14^2-B14^3/3 -> -4.637076e-07 | G14: =_xlfn.NORM.S.INV(RAND())*SQRT($I$4) -> 0.14180981 | H14: =G14^2-$B$3^3/3 -> -0.31322331 | J14: Asimetria | K14: =SKEW(H8:H3007) -> 2.6355651 | L14: =SQRT(8) -> 2.8284271
A15: =A14+1 -> 7 | B15: =A15*$B$5 -> 0.014 | C15: =_xlfn.NORM.S.INV(RAND())*SQRT($B$5) -> 0.023289714 | D15: =D14+B14*C15 -> -5.5624016e-05 | E15: =D15^2-B15^3/3 -> -9.1157264e-07 | G15: =_xlfn.NORM.S.INV(RAND())*SQRT($I$4) -> 0.61882966 | H15: =G15^2-$B$3^3/3 -> 0.049616812 | J15: Minimo | K15: =MIN(H8:H3007) -> -0.33333308 | L15: =-B3^3/3 -> -0.33333333
A16: =A15+1 -> 8 | B16: =A16*$B$5 -> 0.016 | C16: =_xlfn.NORM.S.INV(RAND())*SQRT($B$5) -> 0.082744378 | D16: =D15+B15*C16 -> 0.0011027973 | E16: =D16^2-B16^3/3 -> -1.4917149e-07 | G16: =_xlfn.NORM.S.INV(RAND())*SQRT($I$4) -> 0.089685376 | H16: =G16^2-$B$3^3/3 -> -0.32528987 | J16: e.e. de la media | K16: =K13/SQRT(3000) -> 0.0085147428
A17: =A16+1 -> 9 | B17: =A17*$B$5 -> 0.018 | C17: =_xlfn.NORM.S.INV(RAND())*SQRT($B$5) -> -0.11545989 | D17: =D16+B16*C17 -> -0.00074456091 | E17: =D17^2-B17^3/3 -> -1.389629e-06 | G17: =_xlfn.NORM.S.INV(RAND())*SQRT($I$4) -> -0.041911021 | H17: =G17^2-$B$3^3/3 -> -0.3315768
A18: =A17+1 -> 10 | B18: =A18*$B$5 -> 0.02 | C18: =_xlfn.NORM.S.INV(RAND())*SQRT($B$5) -> 0.11937027 | D18: =D17+B17*C18 -> 0.0014041039 | E18: =D18^2-B18^3/3 -> -6.9515886e-07 | G18: =_xlfn.NORM.S.INV(RAND())*SQRT($I$4) -> 1.4371327 | H18: =G18^2-$B$3^3/3 -> 1.7320171 | J18: M_t = (t^3/3)*(Z^2-1) con Z~N(0,1) => E(M_t)=0 , V(M_t)=2 t^6/9
A19: =A18+1 -> 11 | B19: =A19*$B$5 -> 0.022 | C19: =_xlfn.NORM.S.INV(RAND())*SQRT($B$5) -> 0.05565878 | D19: =D18+B18*C19 -> 0.0025172795 | E19: =D19^2-B19^3/3 -> 2.7873628e-06 | G19: =_xlfn.NORM.S.INV(RAND())*SQRT($I$4) -> 0.26129863 | H19: =G19^2-$B$3^3/3 -> -0.26505636
A20: =A19+1 -> 12 | B20: =A20*$B$5 -> 0.024 | C20: =_xlfn.NORM.S.INV(RAND())*SQRT($B$5) -> -0.066576427 | D20: =D19+B19*C20 -> 0.0010525981 | E20: =D20^2-B20^3/3 -> -3.5000372e-06 | G20: =_xlfn.NORM.S.INV(RAND())*SQRT($I$4) -> -0.77360679 | H20: =G20^2-$B$3^3/3 -> 0.26513414
A21: =A20+1 -> 13 | B21: =A21*$B$5 -> 0.026 | C21: =_xlfn.NORM.S.INV(RAND())*SQRT($B$5) -> -0.038436302 | D21: =D20+B20*C21 -> 0.00013012685 | E21: =D21^2-B21^3/3 -> -5.8417337e-06 | G21: =_xlfn.NORM.S.INV(RAND())*SQRT($I$4) -> 0.2333593 | H21: =G21^2-$B$3^3/3 -> -0.27887677
A22: =A21+1 -> 14 | B22: =A22*$B$5 -> 0.028 | C22: =_xlfn.NORM.S.INV(RAND())*SQRT($B$5) -> -0.023534994 | D22: =D21+B21*C22 -> -0.000481783 | E22: =D22^2-B22^3/3 -> -7.0852185e-06 | G22: =_xlfn.NORM.S.INV(RAND())*SQRT($I$4) -> 0.59378426 | H22: =G22^2-$B$3^3/3 -> 0.019246414
A23: =A22+1 -> 15 | B23: =A23*$B$5 -> 0.03 | C23: =_xlfn.NORM.S.INV(RAND())*SQRT($B$5) -> -0.032841601 | D23: =D22+B22*C23 -> -0.0014013478 | E23: =D23^2-B23^3/3 -> -7.0362243e-06 | G23: =_xlfn.NORM.S.INV(RAND())*SQRT($I$4) -> 0.13670871 | H23: =G23^2-$B$3^3/3 -> -0.31464406
A24: =A23+1 -> 16 | B24: =A24*$B$5 -> 0.032 | C24: =_xlfn.NORM.S.INV(RAND())*SQRT($B$5) -> -0.047852608 | D24: =D23+B23*C24 -> -0.0028369261 | E24: =D24^2-B24^3/3 -> -2.8745172e-06 | G24: =_xlfn.NORM.S.INV(RAND())*SQRT($I$4) -> -0.66491553 | H24: =G24^2-$B$3^3/3 -> 0.10877932
A25: =A24+1 -> 17 | B25: =A25*$B$5 -> 0.034 | C25: =_xlfn.NORM.S.INV(RAND())*SQRT($B$5) -> 0.042819131 | D25: =D24+B24*C25 -> -0.0014667139 | E25: =D25^2-B25^3/3 -> -1.0950084e-05 | G25: =_xlfn.NORM.S.INV(RAND())*SQRT($I$4) -> -0.24314903 | H25: =G25^2-$B$3^3/3 -> -0.27421188
A26: =A25+1 -> 18 | B26: =A26*$B$5 -> 0.036 | C26: =_xlfn.NORM.S.INV(RAND())*SQRT($B$5) -> 0.04900247 | D26: =D25+B25*C26 -> 0.00019937014 | E26: =D26^2-B26^3/3 -> -1.5512252e-05 | G26: =_xlfn.NORM.S.INV(RAND())*SQRT($I$4) -> -0.22140962 | H26: =G26^2-$B$3^3/3 -> -0.28431111
A27: =A26+1 -> 19 | B27: =A27*$B$5 -> 0.038 | C27: =_xlfn.NORM.S.INV(RAND())*SQRT($B$5) -> -0.007967726 | D27: =D26+B26*C27 -> -8.7467995e-05 | E27: =D27^2-B27^3/3 -> -1.8283016e-05 | G27: =_xlfn.NORM.S.INV(RAND())*SQRT($I$4) -> -0.6205005 | H27: =G27^2-$B$3^3/3 -> 0.051687537
A28: =A27+1 -> 20 | B28: =A28*$B$5 -> 0.04 | C28: =_xlfn.NORM.S.INV(RAND())*SQRT($B$5) -> -0.0316427 | D28: =D27+B27*C28 -> -0.0012898906 | E28: =D28^2-B28^3/3 -> -1.9669516e-05 | G28: =_xlfn.NORM.S.INV(RAND())*SQRT($I$4) -> 0.6702805 | H28: =G28^2-$B$3^3/3 -> 0.11594261
A29: =A28+1 -> 21 | B29: =A29*$B$5 -> 0.042 | C29: =_xlfn.NORM.S.INV(RAND())*SQRT($B$5) -> -0.03943337 | D29: =D28+B28*C29 -> -0.0028672254 | E29: =D29^2-B29^3/3 -> -1.6475018e-05 | G29: =_xlfn.NORM.S.INV(RAND())*SQRT($I$4) -> -0.026395794 | H29: =G29^2-$B$3^3/3 -> -0.3326366
A30: =A29+1 -> 22 | B30: =A30*$B$5 -> 0.044 | C30: =_xlfn.NORM.S.INV(RAND())*SQRT($B$5) -> -0.016255569 | D30: =D29+B29*C30 -> -0.0035499593 | E30: =D30^2-B30^3/3 -> -1.5792456e-05 | G30: =_xlfn.NORM.S.INV(RAND())*SQRT($I$4) -> 0.15689351 | H30: =G30^2-$B$3^3/3 -> -0.30871776
... A508: =A507+1 -> 500 | B508: =A508*$B$5 -> 1 | C508: =_xlfn.NORM.S.INV(RAND())*SQRT($B$5) -> -0.05041067 | D508: =D507+B507*C508 -> -0.56639328 | E508: =D508^2-B508^3/3 -> -0.01253198 | G508: =_xlfn.NORM.S.INV(RAND())*SQRT($I$4) -> 0.29327099 | H508: =G508^2-$B$3^3/3 -> -0.24732546
G509: =_xlfn.NORM.S.INV(RAND())*SQRT($I$4) -> -0.16193049 | H509: =G509^2-$B$3^3/3 -> -0.30711185
G510: =_xlfn.NORM.S.INV(RAND())*SQRT($I$4) -> -0.57246378 | H510: =G510^2-$B$3^3/3 -> -0.0056185487
G511: =_xlfn.NORM.S.INV(RAND())*SQRT($I$4) -> 0.35678945 | H511: =G511^2-$B$3^3/3 -> -0.20603462
G512: =_xlfn.NORM.S.INV(RAND())*SQRT($I$4) -> 0.029722553 | H512: =G512^2-$B$3^3/3 -> -0.3324499
G513: =_xlfn.NORM.S.INV(RAND())*SQRT($I$4) -> -0.6136123 | H513: =G513^2-$B$3^3/3 -> 0.043186727
G514: =_xlfn.NORM.S.INV(RAND())*SQRT($I$4) -> -0.10354322 | H514: =G514^2-$B$3^3/3 -> -0.32261214
G515: =_xlfn.NORM.S.INV(RAND())*SQRT($I$4) -> -0.64887256 | H515: =G515^2-$B$3^3/3 -> 0.08770226
G516: =_xlfn.NORM.S.INV(RAND())*SQRT($I$4) -> -0.50940849 | H516: =G516^2-$B$3^3/3 -> -0.073836319
G517: =_xlfn.NORM.S.INV(RAND())*SQRT($I$4) -> -0.013513846 | H517: =G517^2-$B$3^3/3 -> -0.33315071
G518: =_xlfn.NORM.S.INV(RAND())*SQRT($I$4) -> -0.99455519 | H518: =G518^2-$B$3^3/3 -> 0.65580669
G519: =_xlfn.NORM.S.INV(RAND())*SQRT($I$4) -> -0.1179673 | H519: =G519^2-$B$3^3/3 -> -0.31941705
...

Sheet Ej3_Calib
A1: Ejercicio 3 - Calibracion de sigma(t) = a t^2 + b t + c
A3: S0 | B3: 100
A4: K | B4: 100
A5: r | B5: 0.01
A7: a | B7: 0.049958717
A8: b | B8: 0.20009475
A9: c | B9: 0.09988128
A11: Solver: minimizar D17 (suma de errores al cuadrado) cambiando B7:B9. La solucion ya esta introducida.
A13: T | B13: V(T) = Int_0^T sigma^2 | C13: Vol. implicita plana | D13: d1 | E13: d2 | F13: Precio modelo | G13: Precio mercado | H13: Error
A14: 1 | B14: =$B$7^2/5*A14^5+$B$7*$B$8/2*A14^4+($B$8^2+2*$B$7*$B$9)/3*A14^3+$B$8*$B$9*A14^2+$B$9^2*A14 -> 0.052132 | C14: =SQRT(B14/A14) -> 0.22832433 | D14: =(LN($B$3/$B$4)+$B$5*A14+0.5*B14)/SQRT(B14) -> 0.15795951 | E14: =D14-SQRT(B14) -> -0.070364819 | F14: =$B$3*_xlfn.NORM.S.DIST(D14,TRUE)-$B$4*EXP(-$B$5*A14)*_xlfn.NORM.S.DIST(E14,TRUE) -> 9.55 | G14: 9.55 | H14: =F14-G14 -> -3.4710013e-12
A15: 1.25 | B15: =$B$7^2/5*A15^5+$B$7*$B$8/2*A15^4+($B$8^2+2*$B$7*$B$9)/3*A15^3+$B$8*$B$9*A15^2+$B$9^2*A15 -> 0.089987782 | C15: =SQRT(B15/A15) -> 0.26830994 | D15: =(LN($B$3/$B$4)+$B$5*A15+0.5*B15)/SQRT(B15) -> 0.19165931 | E15: =D15-SQRT(B15) -> -0.10832032 | F15: =$B$3*_xlfn.NORM.S.DIST(D15,TRUE)-$B$4*EXP(-$B$5*A15)*_xlfn.NORM.S.DIST(E15,TRUE) -> 12.48 | G15: 12.48 | H15: =F15-G15 -> -6.2208017e-12
A16: 2 | B16: =$B$7^2/5*A16^5+$B$7*$B$8/2*A16^4+($B$8^2+2*$B$7*$B$9)/3*A16^3+$B$8*$B$9*A16^2+$B$9^2*A16 -> 0.3292216 | C16: =SQRT(B16/A16) -> 0.40572257 | D16: =(LN($B$3/$B$4)+$B$5*A16+0.5*B16)/SQRT(B16) -> 0.32174584 | E16: =D16-SQRT(B16) -> -0.25203251 | F16: =$B$3*_xlfn.NORM.S.DIST(D16,TRUE)-$B$4*EXP(-$B$5*A16)*_xlfn.NORM.S.DIST(E16,TRUE) -> 23.36 | G16: 23.36 | H16: =F16-G16 -> -2.4243718e-11
C17: Suma de errores^2 | D17: =SUMSQ(H14:H16) -> 6.3850409e-22
A20: t | B20: sigma(t) | C20: V(t)
A21: 0 | B21: =$B$7*A21^2+$B$8*A21+$B$9 -> 0.09988128 | C21: =$B$7^2/5*A21^5+$B$7*$B$8/2*A21^4+($B$8^2+2*$B$7*$B$9)/3*A21^3+$B$8*$B$9*A21^2+$B$9^2*A21 -> 0
A22: 0.05 | B22: =$B$7*A22^2+$B$8*A22+$B$9 -> 0.11001091 | C22: =$B$7^2/5*A22^5+$B$7*$B$8/2*A22^4+($B$8^2+2*$B$7*$B$9)/3*A22^3+$B$8*$B$9*A22^2+$B$9^2*A22 -> 0.00055089328
A23: 0.1 | B23: =$B$7*A23^2+$B$8*A23+$B$9 -> 0.12039034 | C23: =$B$7^2/5*A23^5+$B$7*$B$8/2*A23^4+($B$8^2+2*$B$7*$B$9)/3*A23^3+$B$8*$B$9*A23^2+$B$9^2*A23 -> 0.0012146616
A24: 0.15 | B24: =$B$7*A24^2+$B$8*A24+$B$9 -> 0.13101956 | C24: =$B$7^2/5*A24^5+$B$7*$B$8/2*A24^4+($B$8^2+2*$B$7*$B$9)/3*A24^3+$B$8*$B$9*A24^2+$B$9^2*A24 -> 0.0020049575
A25: 0.2 | B25: =$B$7*A25^2+$B$8*A25+$B$9 -> 0.14189858 | C25: =$B$7^2/5*A25^5+$B$7*$B$8/2*A25^4+($B$8^2+2*$B$7*$B$9)/3*A25^3+$B$8*$B$9*A25^2+$B$9^2*A25 -> 0.0029362205
A26: 0.25 | B26: =$B$7*A26^2+$B$8*A26+$B$9 -> 0.15302739 | C26: =$B$7^2/5*A26^5+$B$7*$B$8/2*A26^4+($B$8^2+2*$B$7*$B$9)/3*A26^3+$B$8*$B$9*A26^2+$B$9^2*A26 -> 0.0040236962
A27: 0.3 | B27: =$B$7*A27^2+$B$8*A27+$B$9 -> 0.16440599 | C27: =$B$7^2/5*A27^5+$B$7*$B$8/2*A27^4+($B$8^2+2*$B$7*$B$9)/3*A27^3+$B$8*$B$9*A27^2+$B$9^2*A27 -> 0.0052834547
A28: 0.35 | B28: =$B$7*A28^2+$B$8*A28+$B$9 -> 0.17603439 | C28: =$B$7^2/5*A28^5+$B$7*$B$8/2*A28^4+($B$8^2+2*$B$7*$B$9)/3*A28^3+$B$8*$B$9*A28^2+$B$9^2*A28 -> 0.0067324094
A29: 0.4 | B29: =$B$7*A29^2+$B$8*A29+$B$9 -> 0.18791258 | C29: =$B$7^2/5*A29^5+$B$7*$B$8/2*A29^4+($B$8^2+2*$B$7*$B$9)/3*A29^3+$B$8*$B$9*A29^2+$B$9^2*A29 -> 0.0083883359
A30: 0.45 | B30: =$B$7*A30^2+$B$8*A30+$B$9 -> 0.20004056 | C30: =$B$7^2/5*A30^5+$B$7*$B$8/2*A30^4+($B$8^2+2*$B$7*$B$9)/3*A30^3+$B$8*$B$9*A30^2+$B$9^2*A30 -> 0.01026989
A31: 0.5 | B31: =$B$7*A31^2+$B$8*A31+$B$9 -> 0.21241834 | C31: =$B$7^2/5*A31^5+$B$7*$B$8/2*A31^4+($B$8^2+2*$B$7*$B$9)/3*A31^3+$B$8*$B$9*A31^2+$B$9^2*A31 -> 0.012396629
A32: 0.55 | B32: =$B$7*A32^2+$B$8*A32+$B$9 -> 0.22504591 | C32: =$B$7^2/5*A32^5+$B$7*$B$8/2*A32^4+($B$8^2+2*$B$7*$B$9)/3*A32^3+$B$8*$B$9*A32^2+$B$9^2*A32 -> 0.014789025
... A61: 2 | B61: =$B$7*A61^2+$B$8*A61+$B$9 -> 0.69990565 | C61: =$B$7^2/5*A61^5+$B$7*$B$8/2*A61^4+($B$8^2+2*$B$7*$B$9)/3*A61^3+$B$8*$B$9*A61^2+$B$9^2*A61 -> 0.3292216

Sheet Ej3_Asiatica
A1: Ejercicio 3.4 - Opcion asiatica: payoff (media de S en 4 fijaciones - K)+ pagado en T = 2
A3: S0 | B3: =Ej3_Calib!B3 -> 100
A4: K | B4: =Ej3_Calib!B4 -> 100
A5: r | B5: =Ej3_Calib!B5 -> 0.01
A6: T pago | B6: 2
A8: i | B8: t_i | C8: sigma(t_i) | D8: V(t_i) | E8: V(t_i)-V(t_i-1) | F8: sd del salto
A9: 1 | B9: 1.15 | C9: =Ej3_Calib!$B$7*B9^2+Ej3_Calib!$B$8*B9+Ej3_Calib!$B$9 -> 0.39606065 | D9: =Ej3_Calib!$B$7^2/5*B9^5+Ej3_Calib!$B$7*Ej3_Calib!$B$8/2*B9^4+(Ej3_Calib!$B$8^2+2*Ej3_Calib!$B$7*Ej3_Calib!$B$9)/3*B9^3+Ej3_Calib!$B$8*Ej3_Calib!$B$9*B9^2+Ej3_Calib!$B$9^2*B9 -> 0.07300673 | E9: =D9 -> 0.07300673 | F9: =SQRT(E9) -> 0.27019758
A10: 2 | B10: 1.3 | C10: =Ej3_Calib!$B$7*B10^2+Ej3_Calib!$B$8*B10+Ej3_Calib!$B$9 -> 0.44443469 | D10: =Ej3_Calib!$B$7^2/5*B10^5+Ej3_Calib!$B$7*Ej3_Calib!$B$8/2*B10^4+(Ej3_Calib!$B$8^2+2*Ej3_Calib!$B$7*Ej3_Calib!$B$9)/3*B10^3+Ej3_Calib!$B$8*Ej3_Calib!$B$9*B10^2+Ej3_Calib!$B$9^2*B10 -> 0.099503583 | E10: =D10-D9 -> 0.026496853 | F10: =SQRT(E10) -> 0.16277854
A11: 3 | B11: 1.6 | C11: =Ej3_Calib!$B$7*B11^2+Ej3_Calib!$B$8*B11+Ej3_Calib!$B$9 -> 0.5479272 | D11: =Ej3_Calib!$B$7^2/5*B11^5+Ej3_Calib!$B$7*Ej3_Calib!$B$8/2*B11^4+(Ej3_Calib!$B$8^2+2*Ej3_Calib!$B$7*Ej3_Calib!$B$9)/3*B11^3+Ej3_Calib!$B$8*Ej3_Calib!$B$9*B11^2+Ej3_Calib!$B$9^2*B11 -> 0.17340711 | E11: =D11-D10 -> 0.073903531 | F11: =SQRT(E11) -> 0.27185204
A12: 4 | B12: 1.7 | C12: =Ej3_Calib!$B$7*B12^2+Ej3_Calib!$B$8*B12+Ej3_Calib!$B$9 -> 0.58442305 | D12: =Ej3_Calib!$B$7^2/5*B12^5+Ej3_Calib!$B$7*Ej3_Calib!$B$8/2*B12^4+(Ej3_Calib!$B$8^2+2*Ej3_Calib!$B$7*Ej3_Calib!$B$9)/3*B12^3+Ej3_Calib!$B$8*Ej3_Calib!$B$9*B12^2+Ej3_Calib!$B$9^2*B12 -> 0.20546421 | E12: =D12-D11 -> 0.032057099 | F12: =SQRT(E12) -> 0.17904496
A14: SIMULACION (2000 caminos). Simulacion EXACTA: S(t_i) = S0*exp(r t_i - V(t_i)/2 + X_i), X_i = X_(i-1) + sd_i * Z_i
A15: Pulsa F9 para volver a sortear.
A17: Resultados
A18: Precio MC | B18: =AVERAGE(N21:N2020) -> 13.722789 | D18: E[media de S_ti] teorica | F18: =($B$3*EXP($B$5*B9)+$B$3*EXP($B$5*B10)+$B$3*EXP($B$5*B11)+$B$3*EXP($B$5*B12))/4 -> 101.44813
A19: Desviacion tipica | B19: =_xlfn.STDEV.S(N21:N2020) -> 23.519677 | D19: E[media de S_ti] simulada | F19: =AVERAGE(L21:L2020) -> 102.10334
A20: Error estandar | B20: =B19/SQRT(2000) -> 0.52591596 | H20: Z1 | I20: Z2 | J20: Z3 | K20: Z4 | L20: media A | M20: payoff | N20: payoff descontado
A21: IC 95% inferior | B21: =B18-1.96*B20 -> 12.691993 | H21: =_xlfn.NORM.S.INV(RAND()) -> 0.17791991 | I21: =_xlfn.NORM.S.INV(RAND()) -> 1.2608854 | J21: =_xlfn.NORM.S.INV(RAND()) -> 0.38129479 | K21: =_xlfn.NORM.S.INV(RAND()) -> -0.86499742 | L21: =($B$3*EXP($B$5*$B$9-$D$9/2+$F$9*H21)+$B$3*EXP($B$5*$B$10-$D$10/2+$F$9*H21+$F$10*I21)+$B$3*EXP($B$5*$B$11-$D$11/2+$F$9*H21+$F$10*I21+$F$11*J21)+$B$3*EXP($B$5*$B$12-$D$12/2+$F$9*H21+$F$10*I21+$F$11*J21+$F$12*K21))/4 -> 118.00019 | M21: =MAX(L21-$B$4,0) -> 18.000188 | N21: =M21*EXP(-$B$5*$B$6) -> 17.64376
A22: IC 95% superior | B22: =B18+1.96*B20 -> 14.753584 | H22: =_xlfn.NORM.S.INV(RAND()) -> 0.35258911 | I22: =_xlfn.NORM.S.INV(RAND()) -> 0.35682665 | J22: =_xlfn.NORM.S.INV(RAND()) -> -1.1260082 | K22: =_xlfn.NORM.S.INV(RAND()) -> -0.82699554 | L22: =($B$3*EXP($B$5*$B$9-$D$9/2+$F$9*H22)+$B$3*EXP($B$5*$B$10-$D$10/2+$F$9*H22+$F$10*I22)+$B$3*EXP($B$5*$B$11-$D$11/2+$F$9*H22+$F$10*I22+$F$11*J22)+$B$3*EXP($B$5*$B$12-$D$12/2+$F$9*H22+$F$10*I22+$F$11*J22+$F$12*K22))/4 -> 91.890089 | M22: =MAX(L22-$B$4,0) -> 0 | N22: =M22*EXP(-$B$5*$B$6) -> 0
A23: Referencia (2.000.000 caminos + variable de control) | B23: 13.6212 | H23: =_xlfn.NORM.S.INV(RAND()) -> -0.86413043 | I23: =_xlfn.NORM.S.INV(RAND()) -> 0.2705422 | J23: =_xlfn.NORM.S.INV(RAND()) -> -0.54896993 | K23: =_xlfn.NORM.S.INV(RAND()) -> 1.0954231 | L23: =($B$3*EXP($B$5*$B$9-$D$9/2+$F$9*H23)+$B$3*EXP($B$5*$B$10-$D$10/2+$F$9*H23+$F$10*I23)+$B$3*EXP($B$5*$B$11-$D$11/2+$F$9*H23+$F$10*I23+$F$11*J23)+$B$3*EXP($B$5*$B$12-$D$12/2+$F$9*H23+$F$10*I23+$F$11*J23+$F$12*K23))/4 -> 75.743168 | M23: =MAX(L23-$B$4,0) -> 0 | N23: =M23*EXP(-$B$5*$B$6) -> 0
H24: =_xlfn.NORM.S.INV(RAND()) -> -1.8800596 | I24: =_xlfn.NORM.S.INV(RAND()) -> -0.25817809 | J24: =_xlfn.NORM.S.INV(RAND()) -> 1.3328161 | K24: =_xlfn.NORM.S.INV(RAND()) -> -0.25205471 | L24: =($B$3*EXP($B$5*$B$9-$D$9/2+$F$9*H24)+$B$3*EXP($B$5*$B$10-$D$10/2+$F$9*H24+$F$10*I24)+$B$3*EXP($B$5*$B$11-$D$11/2+$F$9*H24+$F$10*I24+$F$11*J24)+$B$3*EXP($B$5*$B$12-$D$12/2+$F$9*H24+$F$10*I24+$F$11*J24+$F$12*K24))/4 -> 66.061789 | M24: =MAX(L24-$B$4,0) -> 0 | N24: =M24*EXP(-$B$5*$B$6) -> 0
H25: =_xlfn.NORM.S.INV(RAND()) -> 0.59085801 | I25: =_xlfn.NORM.S.INV(RAND()) -> 0.42593508 | J25: =_xlfn.NORM.S.INV(RAND()) -> 1.8596843 | K25: =_xlfn.NORM.S.INV(RAND()) -> 0.87508388 | L25: =($B$3*EXP($B$5*$B$9-$D$9/2+$F$9*H25)+$B$3*EXP($B$5*$B$10-$D$10/2+$F$9*H25+$F$10*I25)+$B$3*EXP($B$5*$B$11-$D$11/2+$F$9*H25+$F$10*I25+$F$11*J25)+$B$3*EXP($B$5*$B$12-$D$12/2+$F$9*H25+$F$10*I25+$F$11*J25+$F$12*K25))/4 -> 163.40243 | M25: =MAX(L25-$B$4,0) -> 63.402431 | N25: =M25*EXP(-$B$5*$B$6) -> 62.146979
